Error: the command gunicorn could not be found within PATH or Pipfile's [scripts].
Error: the command gunicorn could not be found within PATH or Pipfile's [scripts].
Error: the command gunicorn could not be found within PATH or Pipfile's [scripts].
Error: the command gunicorn could not be found within PATH or Pipfile's [scripts].
[2020-12-21 14:36:05 +0000] [19973] [INFO] Starting gunicorn 20.0.4
[2020-12-21 14:36:05 +0000] [19973] [INFO] Listening at: http://127.0.0.1:33333 (19973)
[2020-12-21 14:36:05 +0000] [19973] [INFO] Using worker: sync
[2020-12-21 14:36:05 +0000] [19981] [INFO] Booting worker with pid: 19981
Invalid HTTP_HOST header: 'autoapp.elite-house.uz'. You may need to add 'autoapp.elite-house.uz' to ALLOWED_HOSTS.
Bad Request: /
Invalid HTTP_HOST header: 'autoapp.elite-house.uz'. You may need to add 'autoapp.elite-house.uz' to ALLOWED_HOSTS.
Bad Request: /
Invalid HTTP_HOST header: 'autoapp.elite-house.uz'. You may need to add 'autoapp.elite-house.uz' to ALLOWED_HOSTS.
Bad Request: /favicon.ico
[2020-12-21 14:38:12 +0000] [19981] [INFO] Worker exiting (pid: 19981)
[2020-12-21 14:38:12 +0000] [19973] [INFO] Handling signal: term
[2020-12-21 14:38:13 +0000] [19973] [INFO] Shutting down: Master
[2020-12-21 14:38:14 +0000] [20139] [INFO] Starting gunicorn 20.0.4
[2020-12-21 14:38:14 +0000] [20139] [INFO] Listening at: http://127.0.0.1:33333 (20139)
[2020-12-21 14:38:14 +0000] [20139] [INFO] Using worker: sync
[2020-12-21 14:38:14 +0000] [20147] [INFO] Booting worker with pid: 20147
Not Found: /
Not Found: /favicon.ico
[2020-12-21 14:45:59 +0000] [20147] [INFO] Worker exiting (pid: 20147)
[2020-12-21 14:45:59 +0000] [20139] [INFO] Handling signal: term
[2020-12-21 14:45:59 +0000] [20139] [INFO] Shutting down: Master
[2020-12-21 14:46:00 +0000] [20772] [INFO] Starting gunicorn 20.0.4
[2020-12-21 14:46:00 +0000] [20772] [INFO] Listening at: http://127.0.0.1:33333 (20772)
[2020-12-21 14:46:00 +0000] [20772] [INFO] Using worker: sync
[2020-12-21 14:46:00 +0000] [20780] [INFO] Booting worker with pid: 20780
Not Found: /
Not Found: /
Not Found: /favicon.ico
Not Found: /
Not Found: /
[2020-12-22 04:00:02 +0000] [20772] [INFO] Handling signal: term
[2020-12-22 04:00:02 +0000] [20780] [INFO] Worker exiting (pid: 20780)
[2020-12-22 04:00:03 +0000] [20772] [INFO] Shutting down: Master
[2020-12-22 04:00:23 +0000] [5859] [INFO] Starting gunicorn 20.0.4
[2020-12-22 04:00:23 +0000] [5859] [INFO] Listening at: http://127.0.0.1:33333 (5859)
[2020-12-22 04:00:23 +0000] [5859] [INFO] Using worker: sync
[2020-12-22 04:00:23 +0000] [6017] [INFO] Booting worker with pid: 6017
Not Found: /
Not Found: /
[2020-12-23 04:00:01 +0000] [6017] [INFO] Worker exiting (pid: 6017)
[2020-12-23 04:00:01 +0000] [5859] [INFO] Handling signal: term
[2020-12-23 04:00:01 +0000] [5859] [INFO] Shutting down: Master
[2020-12-23 04:00:22 +0000] [862] [INFO] Starting gunicorn 20.0.4
[2020-12-23 04:00:22 +0000] [862] [INFO] Listening at: http://127.0.0.1:33333 (862)
[2020-12-23 04:00:22 +0000] [862] [INFO] Using worker: sync
[2020-12-23 04:00:23 +0000] [1024] [INFO] Booting worker with pid: 1024
[2020-12-23 17:25:37 +0000] [1024] [INFO] Worker exiting (pid: 1024)
[2020-12-23 17:25:37 +0000] [862] [INFO] Handling signal: term
[2020-12-23 17:25:37 +0000] [862] [INFO] Shutting down: Master
[2020-12-23 17:28:47 +0000] [1554] [INFO] Starting gunicorn 20.0.4
[2020-12-23 17:28:47 +0000] [1554] [INFO] Listening at: http://127.0.0.1:33333 (1554)
[2020-12-23 17:28:47 +0000] [1554] [INFO] Using worker: sync
[2020-12-23 17:28:47 +0000] [1775] [INFO] Booting worker with pid: 1775
[2020-12-23 17:38:19 +0000] [1775] [INFO] Worker exiting (pid: 1775)
[2020-12-23 17:38:19 +0000] [1554] [INFO] Handling signal: term
[2020-12-23 17:38:19 +0000] [1554] [INFO] Shutting down: Master
[2020-12-23 17:40:58 +0000] [1598] [INFO] Starting gunicorn 20.0.4
[2020-12-23 17:40:58 +0000] [1598] [INFO] Listening at: http://127.0.0.1:33333 (1598)
[2020-12-23 17:40:58 +0000] [1598] [INFO] Using worker: sync
[2020-12-23 17:40:58 +0000] [1806] [INFO] Booting worker with pid: 1806
Not Found: /
[2020-12-24 04:00:01 +0000] [1806] [INFO] Worker exiting (pid: 1806)
[2020-12-24 04:00:01 +0000] [1598] [INFO] Handling signal: term
[2020-12-24 04:00:01 +0000] [1598] [INFO] Shutting down: Master
[2020-12-24 04:00:27 +0000] [6389] [INFO] Starting gunicorn 20.0.4
[2020-12-24 04:00:27 +0000] [6389] [INFO] Listening at: http://127.0.0.1:33333 (6389)
[2020-12-24 04:00:27 +0000] [6389] [INFO] Using worker: sync
[2020-12-24 04:00:27 +0000] [6574] [INFO] Booting worker with pid: 6574
[2020-12-25 04:00:01 +0000] [6574] [INFO] Worker exiting (pid: 6574)
[2020-12-25 04:00:01 +0000] [6389] [INFO] Handling signal: term
[2020-12-25 04:00:01 +0000] [6389] [INFO] Shutting down: Master
[2020-12-25 04:00:22 +0000] [30679] [INFO] Starting gunicorn 20.0.4
[2020-12-25 04:00:22 +0000] [30679] [INFO] Listening at: http://127.0.0.1:33333 (30679)
[2020-12-25 04:00:22 +0000] [30679] [INFO] Using worker: sync
[2020-12-25 04:00:22 +0000] [30806] [INFO] Booting worker with pid: 30806
[2020-12-26 04:00:01 +0000] [30679] [INFO] Handling signal: term
[2020-12-26 04:00:01 +0000] [30806] [INFO] Worker exiting (pid: 30806)
[2020-12-26 04:00:02 +0000] [30679] [INFO] Shutting down: Master
[2020-12-26 04:00:16 +0000] [21045] [INFO] Starting gunicorn 20.0.4
[2020-12-26 04:00:16 +0000] [21045] [INFO] Listening at: http://127.0.0.1:33333 (21045)
[2020-12-26 04:00:16 +0000] [21045] [INFO] Using worker: sync
[2020-12-26 04:00:16 +0000] [21178] [INFO] Booting worker with pid: 21178
[2020-12-27 04:00:02 +0000] [21045] [INFO] Handling signal: term
[2020-12-27 04:00:02 +0000] [21178] [INFO] Worker exiting (pid: 21178)
[2020-12-27 04:00:02 +0000] [21045] [INFO] Shutting down: Master
[2020-12-27 04:00:19 +0000] [3664] [INFO] Starting gunicorn 20.0.4
[2020-12-27 04:00:19 +0000] [3664] [INFO] Listening at: http://127.0.0.1:33333 (3664)
[2020-12-27 04:00:19 +0000] [3664] [INFO] Using worker: sync
[2020-12-27 04:00:19 +0000] [3785] [INFO] Booting worker with pid: 3785
[2020-12-28 04:00:01 +0000] [3785] [INFO] Worker exiting (pid: 3785)
[2020-12-28 04:00:01 +0000] [3664] [INFO] Handling signal: term
[2020-12-28 04:00:01 +0000] [3664] [INFO] Shutting down: Master
[2020-12-28 04:00:14 +0000] [5473] [INFO] Starting gunicorn 20.0.4
[2020-12-28 04:00:14 +0000] [5473] [INFO] Listening at: http://127.0.0.1:33333 (5473)
[2020-12-28 04:00:14 +0000] [5473] [INFO] Using worker: sync
[2020-12-28 04:00:14 +0000] [5608] [INFO] Booting worker with pid: 5608
[2020-12-29 04:00:01 +0000] [5473] [INFO] Handling signal: term
[2020-12-29 04:00:01 +0000] [5608] [INFO] Worker exiting (pid: 5608)
[2020-12-29 04:00:02 +0000] [5473] [INFO] Shutting down: Master
[2020-12-29 04:00:22 +0000] [16175] [INFO] Starting gunicorn 20.0.4
[2020-12-29 04:00:22 +0000] [16175] [INFO] Listening at: http://127.0.0.1:33333 (16175)
[2020-12-29 04:00:22 +0000] [16175] [INFO] Using worker: sync
[2020-12-29 04:00:22 +0000] [16300] [INFO] Booting worker with pid: 16300
Not Found: /wp-login.php
[2020-12-30 04:00:01 +0000] [16300] [INFO] Worker exiting (pid: 16300)
[2020-12-30 04:00:01 +0000] [16175] [INFO] Handling signal: term
[2020-12-30 04:00:02 +0000] [16175] [INFO] Shutting down: Master
[2020-12-30 04:00:18 +0000] [27977] [INFO] Starting gunicorn 20.0.4
[2020-12-30 04:00:18 +0000] [27977] [INFO] Listening at: http://127.0.0.1:33333 (27977)
[2020-12-30 04:00:18 +0000] [27977] [INFO] Using worker: sync
[2020-12-30 04:00:18 +0000] [28101] [INFO] Booting worker with pid: 28101
Not Found: /
[2020-12-31 04:00:01 +0000] [28101] [INFO] Worker exiting (pid: 28101)
[2020-12-31 04:00:01 +0000] [27977] [INFO] Handling signal: term
[2020-12-31 04:00:01 +0000] [27977] [INFO] Shutting down: Master
[2020-12-31 04:00:19 +0000] [7334] [INFO] Starting gunicorn 20.0.4
[2020-12-31 04:00:19 +0000] [7334] [INFO] Listening at: http://127.0.0.1:33333 (7334)
[2020-12-31 04:00:19 +0000] [7334] [INFO] Using worker: sync
[2020-12-31 04:00:19 +0000] [7461] [INFO] Booting worker with pid: 7461
[2021-01-01 04:00:02 +0000] [7461] [INFO] Worker exiting (pid: 7461)
[2021-01-01 04:00:02 +0000] [7334] [INFO] Handling signal: term
[2021-01-01 04:00:02 +0000] [7334] [INFO] Shutting down: Master
[2021-01-01 04:00:21 +0000] [20765] [INFO] Starting gunicorn 20.0.4
[2021-01-01 04:00:21 +0000] [20765] [INFO] Listening at: http://127.0.0.1:33333 (20765)
[2021-01-01 04:00:21 +0000] [20765] [INFO] Using worker: sync
[2021-01-01 04:00:21 +0000] [20890] [INFO] Booting worker with pid: 20890
[2021-01-02 04:00:02 +0000] [20890] [INFO] Worker exiting (pid: 20890)
[2021-01-02 04:00:02 +0000] [20765] [INFO] Handling signal: term
[2021-01-02 04:00:02 +0000] [20765] [INFO] Shutting down: Master
[2021-01-02 04:00:17 +0000] [28042] [INFO] Starting gunicorn 20.0.4
[2021-01-02 04:00:17 +0000] [28042] [INFO] Listening at: http://127.0.0.1:33333 (28042)
[2021-01-02 04:00:17 +0000] [28042] [INFO] Using worker: sync
[2021-01-02 04:00:17 +0000] [28183] [INFO] Booting worker with pid: 28183
Not Found: /
[2021-01-03 04:00:02 +0000] [28042] [INFO] Handling signal: term
[2021-01-03 04:00:02 +0000] [28183] [INFO] Worker exiting (pid: 28183)
[2021-01-03 04:00:03 +0000] [28042] [INFO] Shutting down: Master
[2021-01-03 04:00:24 +0000] [3642] [INFO] Starting gunicorn 20.0.4
[2021-01-03 04:00:24 +0000] [3642] [INFO] Listening at: http://127.0.0.1:33333 (3642)
[2021-01-03 04:00:24 +0000] [3642] [INFO] Using worker: sync
[2021-01-03 04:00:24 +0000] [3771] [INFO] Booting worker with pid: 3771
Not Found: /
[2021-01-04 04:00:01 +0000] [3771] [INFO] Worker exiting (pid: 3771)
[2021-01-04 04:00:01 +0000] [3642] [INFO] Handling signal: term
[2021-01-04 04:00:01 +0000] [3642] [INFO] Shutting down: Master
[2021-01-04 04:00:20 +0000] [16359] [INFO] Starting gunicorn 20.0.4
[2021-01-04 04:00:20 +0000] [16359] [INFO] Listening at: http://127.0.0.1:33333 (16359)
[2021-01-04 04:00:20 +0000] [16359] [INFO] Using worker: sync
[2021-01-04 04:00:20 +0000] [16497] [INFO] Booting worker with pid: 16497
[2021-01-04 07:08:18 +0000] [16359] [INFO] Handling signal: term
[2021-01-04 07:08:18 +0000] [16497] [INFO] Worker exiting (pid: 16497)
[2021-01-04 07:08:18 +0000] [16359] [INFO] Shutting down: Master
[2021-01-04 07:08:20 +0000] [24519] [INFO] Starting gunicorn 20.0.4
[2021-01-04 07:08:20 +0000] [24519] [INFO] Listening at: http://127.0.0.1:33333 (24519)
[2021-01-04 07:08:20 +0000] [24519] [INFO] Using worker: sync
[2021-01-04 07:08:20 +0000] [24526] [INFO] Booting worker with pid: 24526
[2021-01-05 04:00:01 +0000] [24526] [INFO] Worker exiting (pid: 24526)
[2021-01-05 04:00:01 +0000] [24519] [INFO] Handling signal: term
[2021-01-05 04:00:01 +0000] [24519] [INFO] Shutting down: Master
[2021-01-05 04:00:17 +0000] [31728] [INFO] Starting gunicorn 20.0.4
[2021-01-05 04:00:17 +0000] [31728] [INFO] Listening at: http://127.0.0.1:33333 (31728)
[2021-01-05 04:00:17 +0000] [31728] [INFO] Using worker: sync
[2021-01-05 04:00:17 +0000] [31848] [INFO] Booting worker with pid: 31848
[2021-01-06 04:00:02 +0000] [31848] [INFO] Worker exiting (pid: 31848)
[2021-01-06 04:00:02 +0000] [31728] [INFO] Handling signal: term
[2021-01-06 04:00:02 +0000] [31728] [INFO] Shutting down: Master
[2021-01-06 04:00:22 +0000] [7744] [INFO] Starting gunicorn 20.0.4
[2021-01-06 04:00:22 +0000] [7744] [INFO] Listening at: http://127.0.0.1:33333 (7744)
[2021-01-06 04:00:22 +0000] [7744] [INFO] Using worker: sync
[2021-01-06 04:00:22 +0000] [7863] [INFO] Booting worker with pid: 7863
Not Found: /
[2021-01-07 04:00:01 +0000] [7863] [INFO] Worker exiting (pid: 7863)
[2021-01-07 04:00:01 +0000] [7744] [INFO] Handling signal: term
[2021-01-07 04:00:01 +0000] [7744] [INFO] Shutting down: Master
[2021-01-07 04:00:16 +0000] [29542] [INFO] Starting gunicorn 20.0.4
[2021-01-07 04:00:16 +0000] [29542] [INFO] Listening at: http://127.0.0.1:33333 (29542)
[2021-01-07 04:00:16 +0000] [29542] [INFO] Using worker: sync
[2021-01-07 04:00:16 +0000] [29667] [INFO] Booting worker with pid: 29667
Not Found: /
[2021-01-07 11:52:20 +0000] [29667] [INFO] Worker exiting (pid: 29667)
[2021-01-07 11:52:20 +0000] [29542] [INFO] Handling signal: term
[2021-01-07 11:52:20 +0000] [29542] [INFO] Shutting down: Master
[2021-01-07 11:53:10 +0000] [18510] [INFO] Starting gunicorn 20.0.4
[2021-01-07 11:53:10 +0000] [18510] [INFO] Listening at: http://127.0.0.1:33333 (18510)
[2021-01-07 11:53:10 +0000] [18510] [INFO] Using worker: sync
[2021-01-07 11:53:10 +0000] [18524] [INFO] Booting worker with pid: 18524
[2021-01-08 04:00:01 +0000] [18510] [INFO] Handling signal: term
[2021-01-08 04:00:01 +0000] [18524] [INFO] Worker exiting (pid: 18524)
[2021-01-08 04:00:02 +0000] [18510] [INFO] Shutting down: Master
[2021-01-08 04:00:21 +0000] [21345] [INFO] Starting gunicorn 20.0.4
[2021-01-08 04:00:21 +0000] [21345] [INFO] Listening at: http://127.0.0.1:33333 (21345)
[2021-01-08 04:00:21 +0000] [21345] [INFO] Using worker: sync
[2021-01-08 04:00:21 +0000] [21478] [INFO] Booting worker with pid: 21478
Not Found: /
Not Found: /
[2021-01-09 04:00:01 +0000] [21345] [INFO] Handling signal: term
[2021-01-09 04:00:01 +0000] [21478] [INFO] Worker exiting (pid: 21478)
[2021-01-09 04:00:03 +0000] [21345] [INFO] Shutting down: Master
[2021-01-09 04:00:19 +0000] [6973] [INFO] Starting gunicorn 20.0.4
[2021-01-09 04:00:19 +0000] [6973] [INFO] Listening at: http://127.0.0.1:33333 (6973)
[2021-01-09 04:00:19 +0000] [6973] [INFO] Using worker: sync
[2021-01-09 04:00:19 +0000] [7101] [INFO] Booting worker with pid: 7101
Not Found: /
[2021-01-10 04:00:01 +0000] [6973] [INFO] Handling signal: term
[2021-01-10 04:00:01 +0000] [7101] [INFO] Worker exiting (pid: 7101)
[2021-01-10 04:00:03 +0000] [6973] [INFO] Shutting down: Master
[2021-01-10 04:00:23 +0000] [30012] [INFO] Starting gunicorn 20.0.4
[2021-01-10 04:00:23 +0000] [30012] [INFO] Listening at: http://127.0.0.1:33333 (30012)
[2021-01-10 04:00:23 +0000] [30012] [INFO] Using worker: sync
[2021-01-10 04:00:23 +0000] [30150] [INFO] Booting worker with pid: 30150
[2021-01-11 04:00:02 +0000] [30012] [INFO] Handling signal: term
[2021-01-11 04:00:02 +0000] [30150] [INFO] Worker exiting (pid: 30150)
[2021-01-11 04:00:03 +0000] [30012] [INFO] Shutting down: Master
[2021-01-11 04:00:27 +0000] [8734] [INFO] Starting gunicorn 20.0.4
[2021-01-11 04:00:27 +0000] [8734] [INFO] Listening at: http://127.0.0.1:33333 (8734)
[2021-01-11 04:00:27 +0000] [8734] [INFO] Using worker: sync
[2021-01-11 04:00:27 +0000] [8869] [INFO] Booting worker with pid: 8869
[2021-01-12 04:00:02 +0000] [8734] [INFO] Handling signal: term
[2021-01-12 04:00:02 +0000] [8869] [INFO] Worker exiting (pid: 8869)
[2021-01-12 04:00:03 +0000] [8734] [INFO] Shutting down: Master
[2021-01-12 04:00:29 +0000] [28878] [INFO] Starting gunicorn 20.0.4
[2021-01-12 04:00:29 +0000] [28878] [INFO] Listening at: http://127.0.0.1:33333 (28878)
[2021-01-12 04:00:29 +0000] [28878] [INFO] Using worker: sync
[2021-01-12 04:00:29 +0000] [29008] [INFO] Booting worker with pid: 29008
[2021-01-13 04:00:01 +0000] [29008] [INFO] Worker exiting (pid: 29008)
[2021-01-13 04:00:01 +0000] [28878] [INFO] Handling signal: term
[2021-01-13 04:00:01 +0000] [28878] [INFO] Shutting down: Master
[2021-01-13 04:00:27 +0000] [14389] [INFO] Starting gunicorn 20.0.4
[2021-01-13 04:00:27 +0000] [14389] [INFO] Listening at: http://127.0.0.1:33333 (14389)
[2021-01-13 04:00:27 +0000] [14389] [INFO] Using worker: sync
[2021-01-13 04:00:27 +0000] [14526] [INFO] Booting worker with pid: 14526
Not Found: /
[2021-01-14 04:00:02 +0000] [14526] [INFO] Worker exiting (pid: 14526)
[2021-01-14 04:00:02 +0000] [14389] [INFO] Handling signal: term
[2021-01-14 04:00:02 +0000] [14389] [INFO] Shutting down: Master
[2021-01-14 04:00:27 +0000] [642] [INFO] Starting gunicorn 20.0.4
[2021-01-14 04:00:27 +0000] [642] [INFO] Listening at: http://127.0.0.1:33333 (642)
[2021-01-14 04:00:27 +0000] [642] [INFO] Using worker: sync
[2021-01-14 04:00:27 +0000] [782] [INFO] Booting worker with pid: 782
Not Found: /
Not Found: /
[2021-01-15 04:00:01 +0000] [782] [INFO] Worker exiting (pid: 782)
[2021-01-15 04:00:01 +0000] [642] [INFO] Handling signal: term
[2021-01-15 04:00:01 +0000] [642] [INFO] Shutting down: Master
[2021-01-15 04:00:27 +0000] [23710] [INFO] Starting gunicorn 20.0.4
[2021-01-15 04:00:27 +0000] [23710] [INFO] Listening at: http://127.0.0.1:33333 (23710)
[2021-01-15 04:00:27 +0000] [23710] [INFO] Using worker: sync
[2021-01-15 04:00:27 +0000] [23849] [INFO] Booting worker with pid: 23849
[2021-01-16 04:00:01 +0000] [23849] [INFO] Worker exiting (pid: 23849)
[2021-01-16 04:00:01 +0000] [23710] [INFO] Handling signal: term
[2021-01-16 04:00:01 +0000] [23710] [INFO] Shutting down: Master
[2021-01-16 04:00:25 +0000] [9130] [INFO] Starting gunicorn 20.0.4
[2021-01-16 04:00:25 +0000] [9130] [INFO] Listening at: http://127.0.0.1:33333 (9130)
[2021-01-16 04:00:25 +0000] [9130] [INFO] Using worker: sync
[2021-01-16 04:00:25 +0000] [9271] [INFO] Booting worker with pid: 9271
Not Found: /
Not Found: /favicon.ico
Not Found: /favicon.ico
Not Found: /
Not Found: /
Not Found: /favicon.ico
Method Not Allowed: /register/
Not Found: /static/rest_framework/css/bootstrap.min.css
Not Found: /static/rest_framework/css/bootstrap-tweaks.css
Not Found: /static/rest_framework/css/prettify.css
Not Found: /static/rest_framework/css/default.css
Not Found: /static/rest_framework/js/jquery-3.5.1.min.js
Not Found: /static/rest_framework/js/csrf.js
Not Found: /static/rest_framework/js/bootstrap.min.js
Not Found: /static/rest_framework/js/ajax-form.js
Not Found: /static/rest_framework/js/prettify-min.js
Not Found: /static/rest_framework/js/default.js
Not Found: /static/rest_framework/js/jquery-3.5.1.min.js
Not Found: /static/rest_framework/js/ajax-form.js
Not Found: /static/rest_framework/js/csrf.js
Not Found: /static/rest_framework/js/bootstrap.min.js
Not Found: /static/rest_framework/js/prettify-min.js
Not Found: /static/rest_framework/js/default.js
Method Not Allowed: /register/
Method Not Allowed: /register/
Internal Server Error: /register/
Traceback (most recent call last):
  File "/home/telegrambot/.local/share/virtualenvs/AutoApp-g0zIqH6I/lib/python3.8/site-packages/rest_framework/fields.py", line 457, in get_attribute
    return get_attribute(instance, self.source_attrs)
  File "/home/telegrambot/.local/share/virtualenvs/AutoApp-g0zIqH6I/lib/python3.8/site-packages/rest_framework/fields.py", line 95, in get_attribute
    instance = instance[attr]
KeyError: 'emailOrPhone'

During handling of the above exception, another exception occurred:

Traceback (most recent call last):
  File "/home/telegrambot/.local/share/virtualenvs/AutoApp-g0zIqH6I/lib/python3.8/site-packages/django/core/handlers/exception.py", line 47, in inner
    response = get_response(request)
  File "/home/telegrambot/.local/share/virtualenvs/AutoApp-g0zIqH6I/lib/python3.8/site-packages/django/core/handlers/base.py", line 179, in _get_response
    response = wrapped_callback(request, *callback_args, **callback_kwargs)
  File "/home/telegrambot/.local/share/virtualenvs/AutoApp-g0zIqH6I/lib/python3.8/site-packages/django/views/decorators/csrf.py", line 54, in wrapped_view
    return view_func(*args, **kwargs)
  File "/home/telegrambot/.local/share/virtualenvs/AutoApp-g0zIqH6I/lib/python3.8/site-packages/django/views/generic/base.py", line 70, in view
    return self.dispatch(request, *args, **kwargs)
  File "/home/telegrambot/.local/share/virtualenvs/AutoApp-g0zIqH6I/lib/python3.8/site-packages/rest_framework/views.py", line 509, in dispatch
    response = self.handle_exception(exc)
  File "/home/telegrambot/.local/share/virtualenvs/AutoApp-g0zIqH6I/lib/python3.8/site-packages/rest_framework/views.py", line 469, in handle_exception
    self.raise_uncaught_exception(exc)
  File "/home/telegrambot/.local/share/virtualenvs/AutoApp-g0zIqH6I/lib/python3.8/site-packages/rest_framework/views.py", line 480, in raise_uncaught_exception
    raise exc
  File "/home/telegrambot/.local/share/virtualenvs/AutoApp-g0zIqH6I/lib/python3.8/site-packages/rest_framework/views.py", line 506, in dispatch
    response = handler(request, *args, **kwargs)
  File "/home/telegrambot/AutoApp/Auth/views.py", line 124, in post
    valid = user.validate_register(user.data)
  File "/home/telegrambot/.local/share/virtualenvs/AutoApp-g0zIqH6I/lib/python3.8/site-packages/rest_framework/serializers.py", line 548, in data
    ret = super().data
  File "/home/telegrambot/.local/share/virtualenvs/AutoApp-g0zIqH6I/lib/python3.8/site-packages/rest_framework/serializers.py", line 246, in data
    self._data = self.to_representation(self.instance)
  File "/home/telegrambot/.local/share/virtualenvs/AutoApp-g0zIqH6I/lib/python3.8/site-packages/rest_framework/serializers.py", line 502, in to_representation
    attribute = field.get_attribute(instance)
  File "/home/telegrambot/.local/share/virtualenvs/AutoApp-g0zIqH6I/lib/python3.8/site-packages/rest_framework/fields.py", line 490, in get_attribute
    raise type(exc)(msg)
KeyError: "Got KeyError when attempting to get a value for field `emailOrPhone` on serializer `AccountSerializer`.\nThe serializer field might be named incorrectly and not match any attribute or key on the `dict` instance.\nOriginal exception text was: 'emailOrPhone'."
Method Not Allowed: /register/
Method Not Allowed: /register/
Internal Server Error: /register/
Traceback (most recent call last):
  File "/home/telegrambot/.local/share/virtualenvs/AutoApp-g0zIqH6I/lib/python3.8/site-packages/django/utils/datastructures.py", line 76, in __getitem__
    list_ = super().__getitem__(key)
KeyError: 'provider'

During handling of the above exception, another exception occurred:

Traceback (most recent call last):
  File "/home/telegrambot/.local/share/virtualenvs/AutoApp-g0zIqH6I/lib/python3.8/site-packages/rest_framework/fields.py", line 457, in get_attribute
    return get_attribute(instance, self.source_attrs)
  File "/home/telegrambot/.local/share/virtualenvs/AutoApp-g0zIqH6I/lib/python3.8/site-packages/rest_framework/fields.py", line 95, in get_attribute
    instance = instance[attr]
  File "/home/telegrambot/.local/share/virtualenvs/AutoApp-g0zIqH6I/lib/python3.8/site-packages/django/utils/datastructures.py", line 78, in __getitem__
    raise MultiValueDictKeyError(key)
django.utils.datastructures.MultiValueDictKeyError: 'provider'

During handling of the above exception, another exception occurred:

Traceback (most recent call last):
  File "/home/telegrambot/.local/share/virtualenvs/AutoApp-g0zIqH6I/lib/python3.8/site-packages/django/core/handlers/exception.py", line 47, in inner
    response = get_response(request)
  File "/home/telegrambot/.local/share/virtualenvs/AutoApp-g0zIqH6I/lib/python3.8/site-packages/django/core/handlers/base.py", line 179, in _get_response
    response = wrapped_callback(request, *callback_args, **callback_kwargs)
  File "/home/telegrambot/.local/share/virtualenvs/AutoApp-g0zIqH6I/lib/python3.8/site-packages/django/views/decorators/csrf.py", line 54, in wrapped_view
    return view_func(*args, **kwargs)
  File "/home/telegrambot/.local/share/virtualenvs/AutoApp-g0zIqH6I/lib/python3.8/site-packages/django/views/generic/base.py", line 70, in view
    return self.dispatch(request, *args, **kwargs)
  File "/home/telegrambot/.local/share/virtualenvs/AutoApp-g0zIqH6I/lib/python3.8/site-packages/rest_framework/views.py", line 509, in dispatch
    response = self.handle_exception(exc)
  File "/home/telegrambot/.local/share/virtualenvs/AutoApp-g0zIqH6I/lib/python3.8/site-packages/rest_framework/views.py", line 469, in handle_exception
    self.raise_uncaught_exception(exc)
  File "/home/telegrambot/.local/share/virtualenvs/AutoApp-g0zIqH6I/lib/python3.8/site-packages/rest_framework/views.py", line 480, in raise_uncaught_exception
    raise exc
  File "/home/telegrambot/.local/share/virtualenvs/AutoApp-g0zIqH6I/lib/python3.8/site-packages/rest_framework/views.py", line 506, in dispatch
    response = handler(request, *args, **kwargs)
  File "/home/telegrambot/AutoApp/Auth/views.py", line 124, in post
    valid = user.validate_register(user.data)
  File "/home/telegrambot/.local/share/virtualenvs/AutoApp-g0zIqH6I/lib/python3.8/site-packages/rest_framework/serializers.py", line 548, in data
    ret = super().data
  File "/home/telegrambot/.local/share/virtualenvs/AutoApp-g0zIqH6I/lib/python3.8/site-packages/rest_framework/serializers.py", line 246, in data
    self._data = self.to_representation(self.instance)
  File "/home/telegrambot/.local/share/virtualenvs/AutoApp-g0zIqH6I/lib/python3.8/site-packages/rest_framework/serializers.py", line 502, in to_representation
    attribute = field.get_attribute(instance)
  File "/home/telegrambot/.local/share/virtualenvs/AutoApp-g0zIqH6I/lib/python3.8/site-packages/rest_framework/fields.py", line 490, in get_attribute
    raise type(exc)(msg)
django.utils.datastructures.MultiValueDictKeyError: "Got MultiValueDictKeyError when attempting to get a value for field `provider` on serializer `AccountSerializer`.\nThe serializer field might be named incorrectly and not match any attribute or key on the `QueryDict` instance.\nOriginal exception text was: 'provider'."
Not Found: /wp-login.php
Not Found: /
[2021-01-17 04:00:01 +0000] [9271] [INFO] Worker exiting (pid: 9271)
[2021-01-17 04:00:01 +0000] [9130] [INFO] Handling signal: term
[2021-01-17 04:00:02 +0000] [9130] [INFO] Shutting down: Master
[2021-01-17 04:00:25 +0000] [12346] [INFO] Starting gunicorn 20.0.4
[2021-01-17 04:00:25 +0000] [12346] [INFO] Listening at: http://127.0.0.1:33333 (12346)
[2021-01-17 04:00:25 +0000] [12346] [INFO] Using worker: sync
[2021-01-17 04:00:25 +0000] [12476] [INFO] Booting worker with pid: 12476
Method Not Allowed: /register/
Not Found: /static/rest_framework/css/prettify.css
Not Found: /static/rest_framework/css/bootstrap.min.css
Not Found: /static/rest_framework/css/bootstrap-tweaks.css
Not Found: /static/rest_framework/css/default.css
Not Found: /static/rest_framework/js/ajax-form.js
Not Found: /static/rest_framework/js/jquery-3.5.1.min.js
Method Not Allowed: /register/
Not Found: /static/rest_framework/css/bootstrap.min.css
Not Found: /static/rest_framework/css/bootstrap-tweaks.css
Not Found: /static/rest_framework/css/prettify.css
Not Found: /static/rest_framework/css/default.css
Not Found: /static/rest_framework/js/jquery-3.5.1.min.js
Not Found: /static/rest_framework/js/ajax-form.js
Not Found: /static/rest_framework/js/csrf.js
Not Found: /static/rest_framework/js/bootstrap.min.js
Not Found: /static/rest_framework/js/prettify-min.js
Not Found: /static/rest_framework/js/default.js
Not Found: /static/rest_framework/js/bootstrap.min.js
Not Found: /static/rest_framework/js/prettify-min.js
Not Found: /static/rest_framework/js/default.js
Not Found: /favicon.ico
Not Found: /
Not Found: /static/rest_framework/css/bootstrap.min.css
Not Found: /static/rest_framework/css/prettify.css
Not Found: /static/rest_framework/css/bootstrap-tweaks.css
Not Found: /static/rest_framework/js/jquery-3.5.1.min.js
Not Found: /static/rest_framework/js/ajax-form.js
Not Found: /static/rest_framework/css/default.css
Not Found: /static/rest_framework/js/csrf.js
Not Found: /static/rest_framework/js/bootstrap.min.js
Not Found: /static/rest_framework/js/prettify-min.js
Not Found: /static/rest_framework/js/default.js
Not Found: /static/rest_framework/js/jquery-3.5.1.min.js
Not Found: /static/rest_framework/js/ajax-form.js
Not Found: /static/rest_framework/js/csrf.js
Not Found: /static/rest_framework/js/bootstrap.min.js
Not Found: /static/rest_framework/js/prettify-min.js
Not Found: /static/rest_framework/js/default.js
Not Found: /static/rest_framework/css/bootstrap.min.css
Not Found: /static/rest_framework/css/bootstrap-tweaks.css
Not Found: /static/rest_framework/css/prettify.css
Not Found: /static/rest_framework/css/default.css
Not Found: /static/rest_framework/js/jquery-3.5.1.min.js
Not Found: /static/rest_framework/js/ajax-form.js
Not Found: /static/rest_framework/js/csrf.js
Not Found: /static/rest_framework/js/bootstrap.min.js
Not Found: /static/rest_framework/js/prettify-min.js
Not Found: /static/rest_framework/js/default.js
Not Found: /static/rest_framework/js/prettify-min.js
Not Found: /static/rest_framework/js/default.js
Method Not Allowed: /register/
Not Found: /static/rest_framework/css/bootstrap.min.css
Not Found: /static/rest_framework/css/bootstrap-tweaks.css
Not Found: /static/rest_framework/css/prettify.css
Not Found: /static/rest_framework/css/default.css
Not Found: /static/rest_framework/js/jquery-3.5.1.min.js
Not Found: /static/rest_framework/js/ajax-form.js
Not Found: /static/rest_framework/js/csrf.js
Not Found: /static/rest_framework/js/bootstrap.min.js
Not Found: /static/rest_framework/js/prettify-min.js
Not Found: /static/rest_framework/js/default.js
Not Found: /
[2021-01-18 04:00:01 +0000] [12476] [INFO] Worker exiting (pid: 12476)
[2021-01-18 04:00:01 +0000] [12346] [INFO] Handling signal: term
[2021-01-18 04:00:01 +0000] [12346] [INFO] Shutting down: Master
[2021-01-18 04:00:25 +0000] [32703] [INFO] Starting gunicorn 20.0.4
[2021-01-18 04:00:25 +0000] [32703] [INFO] Listening at: http://127.0.0.1:33333 (32703)
[2021-01-18 04:00:25 +0000] [32703] [INFO] Using worker: sync
[2021-01-18 04:00:25 +0000] [376] [INFO] Booting worker with pid: 376
Not Found: /static/rest_framework/css/bootstrap.min.css
Not Found: /static/rest_framework/css/bootstrap-tweaks.css
Not Found: /static/rest_framework/css/default.css
Not Found: /static/rest_framework/css/prettify.css
Not Found: /static/rest_framework/js/jquery-3.5.1.min.js
Not Found: /static/rest_framework/js/ajax-form.js
Not Found: /static/rest_framework/js/csrf.js
Not Found: /static/rest_framework/js/bootstrap.min.js
Not Found: /static/rest_framework/js/prettify-min.js
Not Found: /static/rest_framework/js/default.js
Not Found: /favicon.ico
Not Found: /static/rest_framework/css/bootstrap.min.css
Not Found: /static/rest_framework/css/bootstrap-tweaks.css
Not Found: /static/rest_framework/css/prettify.css
Not Found: /static/rest_framework/css/default.css
Not Found: /static/rest_framework/js/jquery-3.5.1.min.js
Not Found: /static/rest_framework/js/ajax-form.js
Not Found: /static/rest_framework/js/csrf.js
Not Found: /static/rest_framework/js/bootstrap.min.js
Not Found: /static/rest_framework/js/prettify-min.js
Not Found: /static/rest_framework/js/default.js
Not Found: /favicon.ico
Method Not Allowed: /register/
Not Found: /static/rest_framework/css/bootstrap.min.css
Not Found: /static/rest_framework/css/prettify.css
Not Found: /static/rest_framework/css/bootstrap-tweaks.css
Not Found: /static/rest_framework/css/default.css
Not Found: /static/rest_framework/js/jquery-3.5.1.min.js
Not Found: /static/rest_framework/js/ajax-form.js
Not Found: /static/rest_framework/js/csrf.js
Not Found: /static/rest_framework/js/bootstrap.min.js
Not Found: /static/rest_framework/js/prettify-min.js
Not Found: /static/rest_framework/js/default.js
Method Not Allowed: /register/
Not Found: /static/rest_framework/css/bootstrap.min.css
Not Found: /static/rest_framework/css/bootstrap-tweaks.css
Not Found: /static/rest_framework/css/prettify.css
Not Found: /static/rest_framework/css/default.css
Not Found: /static/rest_framework/js/jquery-3.5.1.min.js
Not Found: /static/rest_framework/js/ajax-form.js
Not Found: /static/rest_framework/js/csrf.js
Not Found: /static/rest_framework/js/bootstrap.min.js
Not Found: /static/rest_framework/js/prettify-min.js
Not Found: /static/rest_framework/js/default.js
Not Found: /static/rest_framework/js/ajax-form.js
Not Found: /static/rest_framework/js/csrf.js
Not Found: /static/rest_framework/js/bootstrap.min.js
Not Found: /static/rest_framework/js/prettify-min.js
Not Found: /static/rest_framework/js/default.js
Not Found: /favicon.ico
Not Found: /
Not Found: /static/admin/css/base.css
Not Found: /static/admin/css/nav_sidebar.css
Not Found: /static/admin/css/login.css
Not Found: /static/admin/css/responsive.css
Not Found: /static/admin/js/nav_sidebar.js
Method Not Allowed: /units/shaxa882@gmail.com/
Not Found: /static/rest_framework/css/bootstrap.min.css
Not Found: /static/rest_framework/css/bootstrap-tweaks.css
Not Found: /static/rest_framework/css/prettify.css
Not Found: /static/rest_framework/js/ajax-form.js
Not Found: /static/rest_framework/css/default.css
Not Found: /static/rest_framework/js/jquery-3.5.1.min.js
Not Found: /static/rest_framework/js/csrf.js
Not Found: /static/rest_framework/js/bootstrap.min.js
Not Found: /static/rest_framework/js/prettify-min.js
Not Found: /static/rest_framework/js/default.js
Not Found: /static/rest_framework/js/ajax-form.js
Not Found: /static/rest_framework/js/csrf.js
Not Found: /static/rest_framework/js/bootstrap.min.js
Not Found: /static/rest_framework/js/prettify-min.js
Not Found: /static/rest_framework/js/default.js
Method Not Allowed: /units/shaxa882@gmail.com/
Not Found: /
[2021-01-19 04:00:02 +0000] [32703] [INFO] Handling signal: term
[2021-01-19 04:00:02 +0000] [376] [INFO] Worker exiting (pid: 376)
[2021-01-19 04:00:03 +0000] [32703] [INFO] Shutting down: Master
[2021-01-19 04:00:26 +0000] [23865] [INFO] Starting gunicorn 20.0.4
[2021-01-19 04:00:26 +0000] [23865] [INFO] Listening at: http://127.0.0.1:33333 (23865)
[2021-01-19 04:00:26 +0000] [23865] [INFO] Using worker: sync
[2021-01-19 04:00:26 +0000] [23998] [INFO] Booting worker with pid: 23998
Method Not Allowed: /units/shaxa882@gmail.com/
Not Found: /static/rest_framework/css/bootstrap.min.css
Not Found: /static/rest_framework/css/prettify.css
Not Found: /static/rest_framework/css/bootstrap-tweaks.css
Not Found: /static/rest_framework/js/ajax-form.js
Not Found: /static/rest_framework/css/default.css
Not Found: /static/rest_framework/js/jquery-3.5.1.min.js
Not Found: /static/rest_framework/js/csrf.js
Not Found: /static/rest_framework/js/prettify-min.js
Not Found: /static/rest_framework/js/bootstrap.min.js
Not Found: /static/rest_framework/js/jquery-3.5.1.min.js
Not Found: /static/rest_framework/js/default.js
Not Found: /static/rest_framework/js/ajax-form.js
Not Found: /static/rest_framework/js/csrf.js
Not Found: /static/rest_framework/js/bootstrap.min.js
Not Found: /static/rest_framework/js/prettify-min.js
Not Found: /static/rest_framework/js/default.js
Not Found: /favicon.ico
[2021-01-19 08:33:09 +0000] [23998] [INFO] Worker exiting (pid: 23998)
[2021-01-19 08:33:09 +0000] [23865] [INFO] Handling signal: term
[2021-01-19 08:33:09 +0000] [23865] [INFO] Shutting down: Master
[2021-01-19 08:33:10 +0000] [32666] [INFO] Starting gunicorn 20.0.4
[2021-01-19 08:33:10 +0000] [32666] [INFO] Listening at: http://127.0.0.1:33333 (32666)
[2021-01-19 08:33:10 +0000] [32666] [INFO] Using worker: sync
[2021-01-19 08:33:10 +0000] [32674] [INFO] Booting worker with pid: 32674
Not Found: /
Not Found: /lo
Not Found: /
Internal Server Error: /loginGoogle/
Traceback (most recent call last):
  File "/home/telegrambot/.local/share/virtualenvs/AutoApp-g0zIqH6I/lib/python3.8/site-packages/django/db/backends/utils.py", line 84, in _execute
    return self.cursor.execute(sql, params)
  File "/home/telegrambot/.local/share/virtualenvs/AutoApp-g0zIqH6I/lib/python3.8/site-packages/django/db/backends/sqlite3/base.py", line 413, in execute
    return Database.Cursor.execute(self, query, params)
sqlite3.OperationalError: no such table: django_session

The above exception was the direct cause of the following exception:

Traceback (most recent call last):
  File "/home/telegrambot/.local/share/virtualenvs/AutoApp-g0zIqH6I/lib/python3.8/site-packages/django/core/handlers/exception.py", line 47, in inner
    response = get_response(request)
  File "/home/telegrambot/.local/share/virtualenvs/AutoApp-g0zIqH6I/lib/python3.8/site-packages/django/utils/deprecation.py", line 116, in __call__
    response = self.process_response(request, response)
  File "/home/telegrambot/.local/share/virtualenvs/AutoApp-g0zIqH6I/lib/python3.8/site-packages/django/contrib/sessions/middleware.py", line 63, in process_response
    request.session.save()
  File "/home/telegrambot/.local/share/virtualenvs/AutoApp-g0zIqH6I/lib/python3.8/site-packages/django/contrib/sessions/backends/db.py", line 81, in save
    return self.create()
  File "/home/telegrambot/.local/share/virtualenvs/AutoApp-g0zIqH6I/lib/python3.8/site-packages/django/contrib/sessions/backends/db.py", line 51, in create
    self._session_key = self._get_new_session_key()
  File "/home/telegrambot/.local/share/virtualenvs/AutoApp-g0zIqH6I/lib/python3.8/site-packages/django/contrib/sessions/backends/base.py", line 196, in _get_new_session_key
    if not self.exists(session_key):
  File "/home/telegrambot/.local/share/virtualenvs/AutoApp-g0zIqH6I/lib/python3.8/site-packages/django/contrib/sessions/backends/db.py", line 47, in exists
    return self.model.objects.filter(session_key=session_key).exists()
  File "/home/telegrambot/.local/share/virtualenvs/AutoApp-g0zIqH6I/lib/python3.8/site-packages/django/db/models/query.py", line 809, in exists
    return self.query.has_results(using=self.db)
  File "/home/telegrambot/.local/share/virtualenvs/AutoApp-g0zIqH6I/lib/python3.8/site-packages/django/db/models/sql/query.py", line 535, in has_results
    return compiler.has_results()
  File "/home/telegrambot/.local/share/virtualenvs/AutoApp-g0zIqH6I/lib/python3.8/site-packages/django/db/models/sql/compiler.py", line 1126, in has_results
    return bool(self.execute_sql(SINGLE))
  File "/home/telegrambot/.local/share/virtualenvs/AutoApp-g0zIqH6I/lib/python3.8/site-packages/django/db/models/sql/compiler.py", line 1156, in execute_sql
    cursor.execute(sql, params)
  File "/home/telegrambot/.local/share/virtualenvs/AutoApp-g0zIqH6I/lib/python3.8/site-packages/django/db/backends/utils.py", line 98, in execute
    return super().execute(sql, params)
  File "/home/telegrambot/.local/share/virtualenvs/AutoApp-g0zIqH6I/lib/python3.8/site-packages/django/db/backends/utils.py", line 66, in execute
    return self._execute_with_wrappers(sql, params, many=False, executor=self._execute)
  File "/home/telegrambot/.local/share/virtualenvs/AutoApp-g0zIqH6I/lib/python3.8/site-packages/django/db/backends/utils.py", line 75, in _execute_with_wrappers
    return executor(sql, params, many, context)
  File "/home/telegrambot/.local/share/virtualenvs/AutoApp-g0zIqH6I/lib/python3.8/site-packages/django/db/backends/utils.py", line 84, in _execute
    return self.cursor.execute(sql, params)
  File "/home/telegrambot/.local/share/virtualenvs/AutoApp-g0zIqH6I/lib/python3.8/site-packages/django/db/utils.py", line 90, in __exit__
    raise dj_exc_value.with_traceback(traceback) from exc_value
  File "/home/telegrambot/.local/share/virtualenvs/AutoApp-g0zIqH6I/lib/python3.8/site-packages/django/db/backends/utils.py", line 84, in _execute
    return self.cursor.execute(sql, params)
  File "/home/telegrambot/.local/share/virtualenvs/AutoApp-g0zIqH6I/lib/python3.8/site-packages/django/db/backends/sqlite3/base.py", line 413, in execute
    return Database.Cursor.execute(self, query, params)
django.db.utils.OperationalError: no such table: django_session
Internal Server Error: /loginGoogle/
Traceback (most recent call last):
  File "/home/telegrambot/.local/share/virtualenvs/AutoApp-g0zIqH6I/lib/python3.8/site-packages/django/db/backends/utils.py", line 84, in _execute
    return self.cursor.execute(sql, params)
  File "/home/telegrambot/.local/share/virtualenvs/AutoApp-g0zIqH6I/lib/python3.8/site-packages/django/db/backends/sqlite3/base.py", line 413, in execute
    return Database.Cursor.execute(self, query, params)
sqlite3.OperationalError: no such table: django_session

The above exception was the direct cause of the following exception:

Traceback (most recent call last):
  File "/home/telegrambot/.local/share/virtualenvs/AutoApp-g0zIqH6I/lib/python3.8/site-packages/django/core/handlers/exception.py", line 47, in inner
    response = get_response(request)
  File "/home/telegrambot/.local/share/virtualenvs/AutoApp-g0zIqH6I/lib/python3.8/site-packages/django/utils/deprecation.py", line 116, in __call__
    response = self.process_response(request, response)
  File "/home/telegrambot/.local/share/virtualenvs/AutoApp-g0zIqH6I/lib/python3.8/site-packages/django/contrib/sessions/middleware.py", line 63, in process_response
    request.session.save()
  File "/home/telegrambot/.local/share/virtualenvs/AutoApp-g0zIqH6I/lib/python3.8/site-packages/django/contrib/sessions/backends/db.py", line 81, in save
    return self.create()
  File "/home/telegrambot/.local/share/virtualenvs/AutoApp-g0zIqH6I/lib/python3.8/site-packages/django/contrib/sessions/backends/db.py", line 51, in create
    self._session_key = self._get_new_session_key()
  File "/home/telegrambot/.local/share/virtualenvs/AutoApp-g0zIqH6I/lib/python3.8/site-packages/django/contrib/sessions/backends/base.py", line 196, in _get_new_session_key
    if not self.exists(session_key):
  File "/home/telegrambot/.local/share/virtualenvs/AutoApp-g0zIqH6I/lib/python3.8/site-packages/django/contrib/sessions/backends/db.py", line 47, in exists
    return self.model.objects.filter(session_key=session_key).exists()
  File "/home/telegrambot/.local/share/virtualenvs/AutoApp-g0zIqH6I/lib/python3.8/site-packages/django/db/models/query.py", line 809, in exists
    return self.query.has_results(using=self.db)
  File "/home/telegrambot/.local/share/virtualenvs/AutoApp-g0zIqH6I/lib/python3.8/site-packages/django/db/models/sql/query.py", line 535, in has_results
    return compiler.has_results()
  File "/home/telegrambot/.local/share/virtualenvs/AutoApp-g0zIqH6I/lib/python3.8/site-packages/django/db/models/sql/compiler.py", line 1126, in has_results
    return bool(self.execute_sql(SINGLE))
  File "/home/telegrambot/.local/share/virtualenvs/AutoApp-g0zIqH6I/lib/python3.8/site-packages/django/db/models/sql/compiler.py", line 1156, in execute_sql
    cursor.execute(sql, params)
  File "/home/telegrambot/.local/share/virtualenvs/AutoApp-g0zIqH6I/lib/python3.8/site-packages/django/db/backends/utils.py", line 98, in execute
    return super().execute(sql, params)
  File "/home/telegrambot/.local/share/virtualenvs/AutoApp-g0zIqH6I/lib/python3.8/site-packages/django/db/backends/utils.py", line 66, in execute
    return self._execute_with_wrappers(sql, params, many=False, executor=self._execute)
  File "/home/telegrambot/.local/share/virtualenvs/AutoApp-g0zIqH6I/lib/python3.8/site-packages/django/db/backends/utils.py", line 75, in _execute_with_wrappers
    return executor(sql, params, many, context)
  File "/home/telegrambot/.local/share/virtualenvs/AutoApp-g0zIqH6I/lib/python3.8/site-packages/django/db/backends/utils.py", line 84, in _execute
    return self.cursor.execute(sql, params)
  File "/home/telegrambot/.local/share/virtualenvs/AutoApp-g0zIqH6I/lib/python3.8/site-packages/django/db/utils.py", line 90, in __exit__
    raise dj_exc_value.with_traceback(traceback) from exc_value
  File "/home/telegrambot/.local/share/virtualenvs/AutoApp-g0zIqH6I/lib/python3.8/site-packages/django/db/backends/utils.py", line 84, in _execute
    return self.cursor.execute(sql, params)
  File "/home/telegrambot/.local/share/virtualenvs/AutoApp-g0zIqH6I/lib/python3.8/site-packages/django/db/backends/sqlite3/base.py", line 413, in execute
    return Database.Cursor.execute(self, query, params)
django.db.utils.OperationalError: no such table: django_session
Not Found: /favicon.ico
[2021-01-19 08:37:44 +0000] [32674] [INFO] Worker exiting (pid: 32674)
[2021-01-19 08:37:44 +0000] [32666] [INFO] Handling signal: term
[2021-01-19 08:37:44 +0000] [32666] [INFO] Shutting down: Master
[2021-01-19 08:37:46 +0000] [359] [INFO] Starting gunicorn 20.0.4
[2021-01-19 08:37:46 +0000] [359] [INFO] Listening at: http://127.0.0.1:33333 (359)
[2021-01-19 08:37:46 +0000] [359] [INFO] Using worker: sync
[2021-01-19 08:37:46 +0000] [366] [INFO] Booting worker with pid: 366
Not Found: /
[2021-01-20 04:00:02 +0000] [366] [INFO] Worker exiting (pid: 366)
[2021-01-20 04:00:02 +0000] [359] [INFO] Handling signal: term
[2021-01-20 04:00:02 +0000] [359] [INFO] Shutting down: Master
[2021-01-20 04:00:27 +0000] [8243] [INFO] Starting gunicorn 20.0.4
[2021-01-20 04:00:27 +0000] [8243] [INFO] Listening at: http://127.0.0.1:33333 (8243)
[2021-01-20 04:00:27 +0000] [8243] [INFO] Using worker: sync
[2021-01-20 04:00:27 +0000] [8373] [INFO] Booting worker with pid: 8373
Not Found: /
Not Found: /favicon.ico
Not Found: /static/admin/css/base.css
Not Found: /static/admin/css/nav_sidebar.css
Not Found: /static/admin/css/login.css
Not Found: /static/admin/css/responsive.css
Not Found: /static/admin/js/nav_sidebar.js
Not Found: /
Not Found: /favicon.ico
Not Found: /
Not Found: /favicon.ico
Not Found: /fullchain.pem
Internal Server Error: /admin/login/
Traceback (most recent call last):
  File "/home/telegrambot/.local/share/virtualenvs/AutoApp-g0zIqH6I/lib/python3.8/site-packages/django/db/backends/utils.py", line 84, in _execute
    return self.cursor.execute(sql, params)
  File "/home/telegrambot/.local/share/virtualenvs/AutoApp-g0zIqH6I/lib/python3.8/site-packages/django/db/backends/sqlite3/base.py", line 413, in execute
    return Database.Cursor.execute(self, query, params)
sqlite3.OperationalError: no such table: auth_user

The above exception was the direct cause of the following exception:

Traceback (most recent call last):
  File "/home/telegrambot/.local/share/virtualenvs/AutoApp-g0zIqH6I/lib/python3.8/site-packages/django/core/handlers/exception.py", line 47, in inner
    response = get_response(request)
  File "/home/telegrambot/.local/share/virtualenvs/AutoApp-g0zIqH6I/lib/python3.8/site-packages/django/core/handlers/base.py", line 179, in _get_response
    response = wrapped_callback(request, *callback_args, **callback_kwargs)
  File "/home/telegrambot/.local/share/virtualenvs/AutoApp-g0zIqH6I/lib/python3.8/site-packages/django/views/decorators/cache.py", line 44, in _wrapped_view_func
    response = view_func(request, *args, **kwargs)
  File "/home/telegrambot/.local/share/virtualenvs/AutoApp-g0zIqH6I/lib/python3.8/site-packages/django/contrib/admin/sites.py", line 410, in login
    return LoginView.as_view(**defaults)(request)
  File "/home/telegrambot/.local/share/virtualenvs/AutoApp-g0zIqH6I/lib/python3.8/site-packages/django/views/generic/base.py", line 70, in view
    return self.dispatch(request, *args, **kwargs)
  File "/home/telegrambot/.local/share/virtualenvs/AutoApp-g0zIqH6I/lib/python3.8/site-packages/django/utils/decorators.py", line 43, in _wrapper
    return bound_method(*args, **kwargs)
  File "/home/telegrambot/.local/share/virtualenvs/AutoApp-g0zIqH6I/lib/python3.8/site-packages/django/views/decorators/debug.py", line 89, in sensitive_post_parameters_wrapper
    return view(request, *args, **kwargs)
  File "/home/telegrambot/.local/share/virtualenvs/AutoApp-g0zIqH6I/lib/python3.8/site-packages/django/utils/decorators.py", line 43, in _wrapper
    return bound_method(*args, **kwargs)
  File "/home/telegrambot/.local/share/virtualenvs/AutoApp-g0zIqH6I/lib/python3.8/site-packages/django/utils/decorators.py", line 130, in _wrapped_view
    response = view_func(request, *args, **kwargs)
  File "/home/telegrambot/.local/share/virtualenvs/AutoApp-g0zIqH6I/lib/python3.8/site-packages/django/utils/decorators.py", line 43, in _wrapper
    return bound_method(*args, **kwargs)
  File "/home/telegrambot/.local/share/virtualenvs/AutoApp-g0zIqH6I/lib/python3.8/site-packages/django/views/decorators/cache.py", line 44, in _wrapped_view_func
    response = view_func(request, *args, **kwargs)
  File "/home/telegrambot/.local/share/virtualenvs/AutoApp-g0zIqH6I/lib/python3.8/site-packages/django/contrib/auth/views.py", line 63, in dispatch
    return super().dispatch(request, *args, **kwargs)
  File "/home/telegrambot/.local/share/virtualenvs/AutoApp-g0zIqH6I/lib/python3.8/site-packages/django/views/generic/base.py", line 98, in dispatch
    return handler(request, *args, **kwargs)
  File "/home/telegrambot/.local/share/virtualenvs/AutoApp-g0zIqH6I/lib/python3.8/site-packages/django/views/generic/edit.py", line 141, in post
    if form.is_valid():
  File "/home/telegrambot/.local/share/virtualenvs/AutoApp-g0zIqH6I/lib/python3.8/site-packages/django/forms/forms.py", line 177, in is_valid
    return self.is_bound and not self.errors
  File "/home/telegrambot/.local/share/virtualenvs/AutoApp-g0zIqH6I/lib/python3.8/site-packages/django/forms/forms.py", line 172, in errors
    self.full_clean()
  File "/home/telegrambot/.local/share/virtualenvs/AutoApp-g0zIqH6I/lib/python3.8/site-packages/django/forms/forms.py", line 375, in full_clean
    self._clean_form()
  File "/home/telegrambot/.local/share/virtualenvs/AutoApp-g0zIqH6I/lib/python3.8/site-packages/django/forms/forms.py", line 402, in _clean_form
    cleaned_data = self.clean()
  File "/home/telegrambot/.local/share/virtualenvs/AutoApp-g0zIqH6I/lib/python3.8/site-packages/django/contrib/auth/forms.py", line 215, in clean
    self.user_cache = authenticate(self.request, username=username, password=password)
  File "/home/telegrambot/.local/share/virtualenvs/AutoApp-g0zIqH6I/lib/python3.8/site-packages/django/contrib/auth/__init__.py", line 73, in authenticate
    user = backend.authenticate(request, **credentials)
  File "/home/telegrambot/.local/share/virtualenvs/AutoApp-g0zIqH6I/lib/python3.8/site-packages/django/contrib/auth/backends.py", line 42, in authenticate
    user = UserModel._default_manager.get_by_natural_key(username)
  File "/home/telegrambot/.local/share/virtualenvs/AutoApp-g0zIqH6I/lib/python3.8/site-packages/django/contrib/auth/base_user.py", line 45, in get_by_natural_key
    return self.get(**{self.model.USERNAME_FIELD: username})
  File "/home/telegrambot/.local/share/virtualenvs/AutoApp-g0zIqH6I/lib/python3.8/site-packages/django/db/models/manager.py", line 85, in manager_method
    return getattr(self.get_queryset(), name)(*args, **kwargs)
  File "/home/telegrambot/.local/share/virtualenvs/AutoApp-g0zIqH6I/lib/python3.8/site-packages/django/db/models/query.py", line 425, in get
    num = len(clone)
  File "/home/telegrambot/.local/share/virtualenvs/AutoApp-g0zIqH6I/lib/python3.8/site-packages/django/db/models/query.py", line 269, in __len__
    self._fetch_all()
  File "/home/telegrambot/.local/share/virtualenvs/AutoApp-g0zIqH6I/lib/python3.8/site-packages/django/db/models/query.py", line 1308, in _fetch_all
    self._result_cache = list(self._iterable_class(self))
  File "/home/telegrambot/.local/share/virtualenvs/AutoApp-g0zIqH6I/lib/python3.8/site-packages/django/db/models/query.py", line 53, in __iter__
    results = compiler.execute_sql(chunked_fetch=self.chunked_fetch, chunk_size=self.chunk_size)
  File "/home/telegrambot/.local/share/virtualenvs/AutoApp-g0zIqH6I/lib/python3.8/site-packages/django/db/models/sql/compiler.py", line 1156, in execute_sql
    cursor.execute(sql, params)
  File "/home/telegrambot/.local/share/virtualenvs/AutoApp-g0zIqH6I/lib/python3.8/site-packages/django/db/backends/utils.py", line 98, in execute
    return super().execute(sql, params)
  File "/home/telegrambot/.local/share/virtualenvs/AutoApp-g0zIqH6I/lib/python3.8/site-packages/django/db/backends/utils.py", line 66, in execute
    return self._execute_with_wrappers(sql, params, many=False, executor=self._execute)
  File "/home/telegrambot/.local/share/virtualenvs/AutoApp-g0zIqH6I/lib/python3.8/site-packages/django/db/backends/utils.py", line 75, in _execute_with_wrappers
    return executor(sql, params, many, context)
  File "/home/telegrambot/.local/share/virtualenvs/AutoApp-g0zIqH6I/lib/python3.8/site-packages/django/db/backends/utils.py", line 84, in _execute
    return self.cursor.execute(sql, params)
  File "/home/telegrambot/.local/share/virtualenvs/AutoApp-g0zIqH6I/lib/python3.8/site-packages/django/db/utils.py", line 90, in __exit__
    raise dj_exc_value.with_traceback(traceback) from exc_value
  File "/home/telegrambot/.local/share/virtualenvs/AutoApp-g0zIqH6I/lib/python3.8/site-packages/django/db/backends/utils.py", line 84, in _execute
    return self.cursor.execute(sql, params)
  File "/home/telegrambot/.local/share/virtualenvs/AutoApp-g0zIqH6I/lib/python3.8/site-packages/django/db/backends/sqlite3/base.py", line 413, in execute
    return Database.Cursor.execute(self, query, params)
django.db.utils.OperationalError: no such table: auth_user
Internal Server Error: /admin/login/
Traceback (most recent call last):
  File "/home/telegrambot/.local/share/virtualenvs/AutoApp-g0zIqH6I/lib/python3.8/site-packages/django/db/backends/utils.py", line 84, in _execute
    return self.cursor.execute(sql, params)
  File "/home/telegrambot/.local/share/virtualenvs/AutoApp-g0zIqH6I/lib/python3.8/site-packages/django/db/backends/sqlite3/base.py", line 413, in execute
    return Database.Cursor.execute(self, query, params)
sqlite3.OperationalError: no such table: auth_user

The above exception was the direct cause of the following exception:

Traceback (most recent call last):
  File "/home/telegrambot/.local/share/virtualenvs/AutoApp-g0zIqH6I/lib/python3.8/site-packages/django/core/handlers/exception.py", line 47, in inner
    response = get_response(request)
  File "/home/telegrambot/.local/share/virtualenvs/AutoApp-g0zIqH6I/lib/python3.8/site-packages/django/core/handlers/base.py", line 179, in _get_response
    response = wrapped_callback(request, *callback_args, **callback_kwargs)
  File "/home/telegrambot/.local/share/virtualenvs/AutoApp-g0zIqH6I/lib/python3.8/site-packages/django/views/decorators/cache.py", line 44, in _wrapped_view_func
    response = view_func(request, *args, **kwargs)
  File "/home/telegrambot/.local/share/virtualenvs/AutoApp-g0zIqH6I/lib/python3.8/site-packages/django/contrib/admin/sites.py", line 410, in login
    return LoginView.as_view(**defaults)(request)
  File "/home/telegrambot/.local/share/virtualenvs/AutoApp-g0zIqH6I/lib/python3.8/site-packages/django/views/generic/base.py", line 70, in view
    return self.dispatch(request, *args, **kwargs)
  File "/home/telegrambot/.local/share/virtualenvs/AutoApp-g0zIqH6I/lib/python3.8/site-packages/django/utils/decorators.py", line 43, in _wrapper
    return bound_method(*args, **kwargs)
  File "/home/telegrambot/.local/share/virtualenvs/AutoApp-g0zIqH6I/lib/python3.8/site-packages/django/views/decorators/debug.py", line 89, in sensitive_post_parameters_wrapper
    return view(request, *args, **kwargs)
  File "/home/telegrambot/.local/share/virtualenvs/AutoApp-g0zIqH6I/lib/python3.8/site-packages/django/utils/decorators.py", line 43, in _wrapper
    return bound_method(*args, **kwargs)
  File "/home/telegrambot/.local/share/virtualenvs/AutoApp-g0zIqH6I/lib/python3.8/site-packages/django/utils/decorators.py", line 130, in _wrapped_view
    response = view_func(request, *args, **kwargs)
  File "/home/telegrambot/.local/share/virtualenvs/AutoApp-g0zIqH6I/lib/python3.8/site-packages/django/utils/decorators.py", line 43, in _wrapper
    return bound_method(*args, **kwargs)
  File "/home/telegrambot/.local/share/virtualenvs/AutoApp-g0zIqH6I/lib/python3.8/site-packages/django/views/decorators/cache.py", line 44, in _wrapped_view_func
    response = view_func(request, *args, **kwargs)
  File "/home/telegrambot/.local/share/virtualenvs/AutoApp-g0zIqH6I/lib/python3.8/site-packages/django/contrib/auth/views.py", line 63, in dispatch
    return super().dispatch(request, *args, **kwargs)
  File "/home/telegrambot/.local/share/virtualenvs/AutoApp-g0zIqH6I/lib/python3.8/site-packages/django/views/generic/base.py", line 98, in dispatch
    return handler(request, *args, **kwargs)
  File "/home/telegrambot/.local/share/virtualenvs/AutoApp-g0zIqH6I/lib/python3.8/site-packages/django/views/generic/edit.py", line 141, in post
    if form.is_valid():
  File "/home/telegrambot/.local/share/virtualenvs/AutoApp-g0zIqH6I/lib/python3.8/site-packages/django/forms/forms.py", line 177, in is_valid
    return self.is_bound and not self.errors
  File "/home/telegrambot/.local/share/virtualenvs/AutoApp-g0zIqH6I/lib/python3.8/site-packages/django/forms/forms.py", line 172, in errors
    self.full_clean()
  File "/home/telegrambot/.local/share/virtualenvs/AutoApp-g0zIqH6I/lib/python3.8/site-packages/django/forms/forms.py", line 375, in full_clean
    self._clean_form()
  File "/home/telegrambot/.local/share/virtualenvs/AutoApp-g0zIqH6I/lib/python3.8/site-packages/django/forms/forms.py", line 402, in _clean_form
    cleaned_data = self.clean()
  File "/home/telegrambot/.local/share/virtualenvs/AutoApp-g0zIqH6I/lib/python3.8/site-packages/django/contrib/auth/forms.py", line 215, in clean
    self.user_cache = authenticate(self.request, username=username, password=password)
  File "/home/telegrambot/.local/share/virtualenvs/AutoApp-g0zIqH6I/lib/python3.8/site-packages/django/contrib/auth/__init__.py", line 73, in authenticate
    user = backend.authenticate(request, **credentials)
  File "/home/telegrambot/.local/share/virtualenvs/AutoApp-g0zIqH6I/lib/python3.8/site-packages/django/contrib/auth/backends.py", line 42, in authenticate
    user = UserModel._default_manager.get_by_natural_key(username)
  File "/home/telegrambot/.local/share/virtualenvs/AutoApp-g0zIqH6I/lib/python3.8/site-packages/django/contrib/auth/base_user.py", line 45, in get_by_natural_key
    return self.get(**{self.model.USERNAME_FIELD: username})
  File "/home/telegrambot/.local/share/virtualenvs/AutoApp-g0zIqH6I/lib/python3.8/site-packages/django/db/models/manager.py", line 85, in manager_method
    return getattr(self.get_queryset(), name)(*args, **kwargs)
  File "/home/telegrambot/.local/share/virtualenvs/AutoApp-g0zIqH6I/lib/python3.8/site-packages/django/db/models/query.py", line 425, in get
    num = len(clone)
  File "/home/telegrambot/.local/share/virtualenvs/AutoApp-g0zIqH6I/lib/python3.8/site-packages/django/db/models/query.py", line 269, in __len__
    self._fetch_all()
  File "/home/telegrambot/.local/share/virtualenvs/AutoApp-g0zIqH6I/lib/python3.8/site-packages/django/db/models/query.py", line 1308, in _fetch_all
    self._result_cache = list(self._iterable_class(self))
  File "/home/telegrambot/.local/share/virtualenvs/AutoApp-g0zIqH6I/lib/python3.8/site-packages/django/db/models/query.py", line 53, in __iter__
    results = compiler.execute_sql(chunked_fetch=self.chunked_fetch, chunk_size=self.chunk_size)
  File "/home/telegrambot/.local/share/virtualenvs/AutoApp-g0zIqH6I/lib/python3.8/site-packages/django/db/models/sql/compiler.py", line 1156, in execute_sql
    cursor.execute(sql, params)
  File "/home/telegrambot/.local/share/virtualenvs/AutoApp-g0zIqH6I/lib/python3.8/site-packages/django/db/backends/utils.py", line 98, in execute
    return super().execute(sql, params)
  File "/home/telegrambot/.local/share/virtualenvs/AutoApp-g0zIqH6I/lib/python3.8/site-packages/django/db/backends/utils.py", line 66, in execute
    return self._execute_with_wrappers(sql, params, many=False, executor=self._execute)
  File "/home/telegrambot/.local/share/virtualenvs/AutoApp-g0zIqH6I/lib/python3.8/site-packages/django/db/backends/utils.py", line 75, in _execute_with_wrappers
    return executor(sql, params, many, context)
  File "/home/telegrambot/.local/share/virtualenvs/AutoApp-g0zIqH6I/lib/python3.8/site-packages/django/db/backends/utils.py", line 84, in _execute
    return self.cursor.execute(sql, params)
  File "/home/telegrambot/.local/share/virtualenvs/AutoApp-g0zIqH6I/lib/python3.8/site-packages/django/db/utils.py", line 90, in __exit__
    raise dj_exc_value.with_traceback(traceback) from exc_value
  File "/home/telegrambot/.local/share/virtualenvs/AutoApp-g0zIqH6I/lib/python3.8/site-packages/django/db/backends/utils.py", line 84, in _execute
    return self.cursor.execute(sql, params)
  File "/home/telegrambot/.local/share/virtualenvs/AutoApp-g0zIqH6I/lib/python3.8/site-packages/django/db/backends/sqlite3/base.py", line 413, in execute
    return Database.Cursor.execute(self, query, params)
django.db.utils.OperationalError: no such table: auth_user
Not Found: /
[2021-01-21 04:00:01 +0000] [8373] [INFO] Worker exiting (pid: 8373)
[2021-01-21 04:00:01 +0000] [8243] [INFO] Handling signal: term
[2021-01-21 04:00:01 +0000] [8243] [INFO] Shutting down: Master
[2021-01-21 04:00:27 +0000] [4373] [INFO] Starting gunicorn 20.0.4
[2021-01-21 04:00:27 +0000] [4373] [INFO] Listening at: http://127.0.0.1:33333 (4373)
[2021-01-21 04:00:27 +0000] [4373] [INFO] Using worker: sync
[2021-01-21 04:00:27 +0000] [4504] [INFO] Booting worker with pid: 4504
Not Found: /
[2021-01-22 04:00:01 +0000] [4373] [INFO] Handling signal: term
[2021-01-22 04:00:01 +0000] [4504] [INFO] Worker exiting (pid: 4504)
[2021-01-22 04:00:03 +0000] [4373] [INFO] Shutting down: Master
[2021-01-22 04:00:29 +0000] [32193] [INFO] Starting gunicorn 20.0.4
[2021-01-22 04:00:29 +0000] [32193] [INFO] Listening at: http://127.0.0.1:33333 (32193)
[2021-01-22 04:00:29 +0000] [32193] [INFO] Using worker: sync
[2021-01-22 04:00:29 +0000] [32326] [INFO] Booting worker with pid: 32326
Not Found: /
[2021-01-23 04:00:02 +0000] [32193] [INFO] Handling signal: term
[2021-01-23 04:00:02 +0000] [32326] [INFO] Worker exiting (pid: 32326)
[2021-01-23 04:00:04 +0000] [32193] [INFO] Shutting down: Master
[2021-01-23 04:00:28 +0000] [25524] [INFO] Starting gunicorn 20.0.4
[2021-01-23 04:00:28 +0000] [25524] [INFO] Listening at: http://127.0.0.1:33333 (25524)
[2021-01-23 04:00:28 +0000] [25524] [INFO] Using worker: sync
[2021-01-23 04:00:28 +0000] [25665] [INFO] Booting worker with pid: 25665
[2021-01-23 07:44:27 +0000] [25665] [INFO] Worker exiting (pid: 25665)
[2021-01-23 07:44:27 +0000] [25524] [INFO] Handling signal: term
[2021-01-23 07:44:27 +0000] [25524] [INFO] Shutting down: Master
[2021-01-23 07:44:29 +0000] [2878] [INFO] Starting gunicorn 20.0.4
[2021-01-23 07:44:29 +0000] [2878] [INFO] Listening at: http://127.0.0.1:33333 (2878)
[2021-01-23 07:44:29 +0000] [2878] [INFO] Using worker: sync
[2021-01-23 07:44:29 +0000] [2885] [INFO] Booting worker with pid: 2885
Not Found: /
Not Found: /favicon.ico
Internal Server Error: /units/null/
Traceback (most recent call last):
  File "/home/telegrambot/.local/share/virtualenvs/AutoApp-g0zIqH6I/lib/python3.8/site-packages/django/core/handlers/exception.py", line 47, in inner
    response = get_response(request)
  File "/home/telegrambot/.local/share/virtualenvs/AutoApp-g0zIqH6I/lib/python3.8/site-packages/django/core/handlers/base.py", line 179, in _get_response
    response = wrapped_callback(request, *callback_args, **callback_kwargs)
  File "/home/telegrambot/.local/share/virtualenvs/AutoApp-g0zIqH6I/lib/python3.8/site-packages/django/views/decorators/csrf.py", line 54, in wrapped_view
    return view_func(*args, **kwargs)
  File "/home/telegrambot/.local/share/virtualenvs/AutoApp-g0zIqH6I/lib/python3.8/site-packages/django/views/generic/base.py", line 70, in view
    return self.dispatch(request, *args, **kwargs)
  File "/home/telegrambot/.local/share/virtualenvs/AutoApp-g0zIqH6I/lib/python3.8/site-packages/rest_framework/views.py", line 509, in dispatch
    response = self.handle_exception(exc)
  File "/home/telegrambot/.local/share/virtualenvs/AutoApp-g0zIqH6I/lib/python3.8/site-packages/rest_framework/views.py", line 469, in handle_exception
    self.raise_uncaught_exception(exc)
  File "/home/telegrambot/.local/share/virtualenvs/AutoApp-g0zIqH6I/lib/python3.8/site-packages/rest_framework/views.py", line 480, in raise_uncaught_exception
    raise exc
  File "/home/telegrambot/.local/share/virtualenvs/AutoApp-g0zIqH6I/lib/python3.8/site-packages/rest_framework/views.py", line 506, in dispatch
    response = handler(request, *args, **kwargs)
  File "/home/telegrambot/AutoApp/Auth/views.py", line 144, in put
    user = UserTransport.objects.get(emailOrPhone=pk)
  File "/home/telegrambot/.local/share/virtualenvs/AutoApp-g0zIqH6I/lib/python3.8/site-packages/django/db/models/manager.py", line 85, in manager_method
    return getattr(self.get_queryset(), name)(*args, **kwargs)
  File "/home/telegrambot/.local/share/virtualenvs/AutoApp-g0zIqH6I/lib/python3.8/site-packages/django/db/models/query.py", line 429, in get
    raise self.model.DoesNotExist(
Auth.models.UserTransport.DoesNotExist: UserTransport matching query does not exist.
Not Found: /
Not Found: /favicon.ico
Not Found: /
Not Found: /favicon.ico
[2021-01-23 13:49:11 +0000] [2885] [INFO] Worker exiting (pid: 2885)
[2021-01-23 13:49:11 +0000] [2878] [INFO] Handling signal: term
[2021-01-23 13:49:11 +0000] [2878] [INFO] Shutting down: Master
[2021-01-23 13:49:12 +0000] [16736] [INFO] Starting gunicorn 20.0.4
[2021-01-23 13:49:12 +0000] [16736] [INFO] Listening at: http://127.0.0.1:33333 (16736)
[2021-01-23 13:49:12 +0000] [16736] [INFO] Using worker: sync
[2021-01-23 13:49:12 +0000] [16745] [INFO] Booting worker with pid: 16745
Method Not Allowed: /transport/null/
Method Not Allowed: /transport/nccbbch@yh.hy/
Method Not Allowed: /transport/aaa@a.j/
Not Found: /wp-login.php
Not Found: /robots.txt
[2021-01-24 04:00:01 +0000] [16736] [INFO] Handling signal: term
[2021-01-24 04:00:01 +0000] [16745] [INFO] Worker exiting (pid: 16745)
[2021-01-24 04:00:03 +0000] [16736] [INFO] Shutting down: Master
[2021-01-24 04:00:26 +0000] [13031] [INFO] Starting gunicorn 20.0.4
[2021-01-24 04:00:26 +0000] [13031] [INFO] Listening at: http://127.0.0.1:33333 (13031)
[2021-01-24 04:00:26 +0000] [13031] [INFO] Using worker: sync
[2021-01-24 04:00:26 +0000] [13162] [INFO] Booting worker with pid: 13162
[2021-01-25 04:00:01 +0000] [13162] [INFO] Worker exiting (pid: 13162)
[2021-01-25 04:00:01 +0000] [13031] [INFO] Handling signal: term
[2021-01-25 04:00:02 +0000] [13031] [INFO] Shutting down: Master
[2021-01-25 04:00:27 +0000] [31037] [INFO] Starting gunicorn 20.0.4
[2021-01-25 04:00:27 +0000] [31037] [INFO] Listening at: http://127.0.0.1:33333 (31037)
[2021-01-25 04:00:27 +0000] [31037] [INFO] Using worker: sync
[2021-01-25 04:00:27 +0000] [31184] [INFO] Booting worker with pid: 31184
Not Found: /favicon.ico
[2021-01-26 04:00:02 +0000] [31037] [INFO] Handling signal: term
[2021-01-26 04:00:02 +0000] [31184] [INFO] Worker exiting (pid: 31184)
[2021-01-26 04:00:03 +0000] [31037] [INFO] Shutting down: Master
[2021-01-26 04:00:27 +0000] [18181] [INFO] Starting gunicorn 20.0.4
[2021-01-26 04:00:27 +0000] [18181] [INFO] Listening at: http://127.0.0.1:33333 (18181)
[2021-01-26 04:00:27 +0000] [18181] [INFO] Using worker: sync
[2021-01-26 04:00:27 +0000] [18320] [INFO] Booting worker with pid: 18320
Internal Server Error: /units/null/
Traceback (most recent call last):
  File "/home/telegrambot/.local/share/virtualenvs/AutoApp-g0zIqH6I/lib/python3.8/site-packages/django/core/handlers/exception.py", line 47, in inner
    response = get_response(request)
  File "/home/telegrambot/.local/share/virtualenvs/AutoApp-g0zIqH6I/lib/python3.8/site-packages/django/core/handlers/base.py", line 179, in _get_response
    response = wrapped_callback(request, *callback_args, **callback_kwargs)
  File "/home/telegrambot/.local/share/virtualenvs/AutoApp-g0zIqH6I/lib/python3.8/site-packages/django/views/decorators/csrf.py", line 54, in wrapped_view
    return view_func(*args, **kwargs)
  File "/home/telegrambot/.local/share/virtualenvs/AutoApp-g0zIqH6I/lib/python3.8/site-packages/django/views/generic/base.py", line 70, in view
    return self.dispatch(request, *args, **kwargs)
  File "/home/telegrambot/.local/share/virtualenvs/AutoApp-g0zIqH6I/lib/python3.8/site-packages/rest_framework/views.py", line 509, in dispatch
    response = self.handle_exception(exc)
  File "/home/telegrambot/.local/share/virtualenvs/AutoApp-g0zIqH6I/lib/python3.8/site-packages/rest_framework/views.py", line 469, in handle_exception
    self.raise_uncaught_exception(exc)
  File "/home/telegrambot/.local/share/virtualenvs/AutoApp-g0zIqH6I/lib/python3.8/site-packages/rest_framework/views.py", line 480, in raise_uncaught_exception
    raise exc
  File "/home/telegrambot/.local/share/virtualenvs/AutoApp-g0zIqH6I/lib/python3.8/site-packages/rest_framework/views.py", line 506, in dispatch
    response = handler(request, *args, **kwargs)
  File "/home/telegrambot/AutoApp/Auth/views.py", line 143, in put
    user = UserTransport.objects.get(emailOrPhone=pk)
  File "/home/telegrambot/.local/share/virtualenvs/AutoApp-g0zIqH6I/lib/python3.8/site-packages/django/db/models/manager.py", line 85, in manager_method
    return getattr(self.get_queryset(), name)(*args, **kwargs)
  File "/home/telegrambot/.local/share/virtualenvs/AutoApp-g0zIqH6I/lib/python3.8/site-packages/django/db/models/query.py", line 429, in get
    raise self.model.DoesNotExist(
Auth.models.UserTransport.DoesNotExist: UserTransport matching query does not exist.
Internal Server Error: /units/null/
Traceback (most recent call last):
  File "/home/telegrambot/.local/share/virtualenvs/AutoApp-g0zIqH6I/lib/python3.8/site-packages/django/core/handlers/exception.py", line 47, in inner
    response = get_response(request)
  File "/home/telegrambot/.local/share/virtualenvs/AutoApp-g0zIqH6I/lib/python3.8/site-packages/django/core/handlers/base.py", line 179, in _get_response
    response = wrapped_callback(request, *callback_args, **callback_kwargs)
  File "/home/telegrambot/.local/share/virtualenvs/AutoApp-g0zIqH6I/lib/python3.8/site-packages/django/views/decorators/csrf.py", line 54, in wrapped_view
    return view_func(*args, **kwargs)
  File "/home/telegrambot/.local/share/virtualenvs/AutoApp-g0zIqH6I/lib/python3.8/site-packages/django/views/generic/base.py", line 70, in view
    return self.dispatch(request, *args, **kwargs)
  File "/home/telegrambot/.local/share/virtualenvs/AutoApp-g0zIqH6I/lib/python3.8/site-packages/rest_framework/views.py", line 509, in dispatch
    response = self.handle_exception(exc)
  File "/home/telegrambot/.local/share/virtualenvs/AutoApp-g0zIqH6I/lib/python3.8/site-packages/rest_framework/views.py", line 469, in handle_exception
    self.raise_uncaught_exception(exc)
  File "/home/telegrambot/.local/share/virtualenvs/AutoApp-g0zIqH6I/lib/python3.8/site-packages/rest_framework/views.py", line 480, in raise_uncaught_exception
    raise exc
  File "/home/telegrambot/.local/share/virtualenvs/AutoApp-g0zIqH6I/lib/python3.8/site-packages/rest_framework/views.py", line 506, in dispatch
    response = handler(request, *args, **kwargs)
  File "/home/telegrambot/AutoApp/Auth/views.py", line 143, in put
    user = UserTransport.objects.get(emailOrPhone=pk)
  File "/home/telegrambot/.local/share/virtualenvs/AutoApp-g0zIqH6I/lib/python3.8/site-packages/django/db/models/manager.py", line 85, in manager_method
    return getattr(self.get_queryset(), name)(*args, **kwargs)
  File "/home/telegrambot/.local/share/virtualenvs/AutoApp-g0zIqH6I/lib/python3.8/site-packages/django/db/models/query.py", line 429, in get
    raise self.model.DoesNotExist(
Auth.models.UserTransport.DoesNotExist: UserTransport matching query does not exist.
[2021-01-27 04:00:01 +0000] [18181] [INFO] Handling signal: term
[2021-01-27 04:00:01 +0000] [18320] [INFO] Worker exiting (pid: 18320)
[2021-01-27 04:00:02 +0000] [18181] [INFO] Shutting down: Master
[2021-01-27 04:00:25 +0000] [8811] [INFO] Starting gunicorn 20.0.4
[2021-01-27 04:00:25 +0000] [8811] [INFO] Listening at: http://127.0.0.1:33333 (8811)
[2021-01-27 04:00:25 +0000] [8811] [INFO] Using worker: sync
[2021-01-27 04:00:25 +0000] [8950] [INFO] Booting worker with pid: 8950
[2021-01-28 04:00:02 +0000] [8950] [INFO] Worker exiting (pid: 8950)
[2021-01-28 04:00:02 +0000] [8811] [INFO] Handling signal: term
[2021-01-28 04:00:03 +0000] [8811] [INFO] Shutting down: Master
[2021-01-28 04:00:27 +0000] [28754] [INFO] Starting gunicorn 20.0.4
[2021-01-28 04:00:27 +0000] [28754] [INFO] Listening at: http://127.0.0.1:33333 (28754)
[2021-01-28 04:00:27 +0000] [28754] [INFO] Using worker: sync
[2021-01-28 04:00:27 +0000] [28902] [INFO] Booting worker with pid: 28902
Not Found: /
[2021-01-29 04:00:01 +0000] [28902] [INFO] Worker exiting (pid: 28902)
[2021-01-29 04:00:01 +0000] [28754] [INFO] Handling signal: term
[2021-01-29 04:00:01 +0000] [28754] [INFO] Shutting down: Master
[2021-01-29 04:00:27 +0000] [24417] [INFO] Starting gunicorn 20.0.4
[2021-01-29 04:00:27 +0000] [24417] [INFO] Listening at: http://127.0.0.1:33333 (24417)
[2021-01-29 04:00:27 +0000] [24417] [INFO] Using worker: sync
[2021-01-29 04:00:27 +0000] [24548] [INFO] Booting worker with pid: 24548
Not Found: /
Not Found: /wp-login.php
Not Found: /wp-login.php
Not Found: /
[2021-01-30 04:00:01 +0000] [24548] [INFO] Worker exiting (pid: 24548)
[2021-01-30 04:00:01 +0000] [24417] [INFO] Handling signal: term
[2021-01-30 04:00:01 +0000] [24417] [INFO] Shutting down: Master
[2021-01-30 04:00:26 +0000] [12900] [INFO] Starting gunicorn 20.0.4
[2021-01-30 04:00:26 +0000] [12900] [INFO] Listening at: http://127.0.0.1:33333 (12900)
[2021-01-30 04:00:26 +0000] [12900] [INFO] Using worker: sync
[2021-01-30 04:00:26 +0000] [13032] [INFO] Booting worker with pid: 13032
[2021-01-31 04:00:02 +0000] [12900] [INFO] Handling signal: term
[2021-01-31 04:00:02 +0000] [13032] [INFO] Worker exiting (pid: 13032)
[2021-01-31 04:00:03 +0000] [12900] [INFO] Shutting down: Master
[2021-01-31 04:00:28 +0000] [30561] [INFO] Starting gunicorn 20.0.4
[2021-01-31 04:00:28 +0000] [30561] [INFO] Listening at: http://127.0.0.1:33333 (30561)
[2021-01-31 04:00:28 +0000] [30561] [INFO] Using worker: sync
[2021-01-31 04:00:28 +0000] [30708] [INFO] Booting worker with pid: 30708
Not Found: /
[2021-02-01 04:00:02 +0000] [30708] [INFO] Worker exiting (pid: 30708)
[2021-02-01 04:00:02 +0000] [30561] [INFO] Handling signal: term
[2021-02-01 04:00:03 +0000] [30561] [INFO] Shutting down: Master
[2021-02-01 04:00:27 +0000] [17629] [INFO] Starting gunicorn 20.0.4
[2021-02-01 04:00:27 +0000] [17629] [INFO] Listening at: http://127.0.0.1:33333 (17629)
[2021-02-01 04:00:27 +0000] [17629] [INFO] Using worker: sync
[2021-02-01 04:00:27 +0000] [17776] [INFO] Booting worker with pid: 17776
Internal Server Error: /transport/
Traceback (most recent call last):
  File "/home/telegrambot/.local/share/virtualenvs/AutoApp-g0zIqH6I/lib/python3.8/site-packages/django/db/backends/utils.py", line 84, in _execute
    return self.cursor.execute(sql, params)
  File "/home/telegrambot/.local/share/virtualenvs/AutoApp-g0zIqH6I/lib/python3.8/site-packages/django/db/backends/sqlite3/base.py", line 413, in execute
    return Database.Cursor.execute(self, query, params)
sqlite3.OperationalError: no such table: Auth_usertransport

The above exception was the direct cause of the following exception:

Traceback (most recent call last):
  File "/home/telegrambot/.local/share/virtualenvs/AutoApp-g0zIqH6I/lib/python3.8/site-packages/django/core/handlers/exception.py", line 47, in inner
    response = get_response(request)
  File "/home/telegrambot/.local/share/virtualenvs/AutoApp-g0zIqH6I/lib/python3.8/site-packages/django/core/handlers/base.py", line 179, in _get_response
    response = wrapped_callback(request, *callback_args, **callback_kwargs)
  File "/home/telegrambot/.local/share/virtualenvs/AutoApp-g0zIqH6I/lib/python3.8/site-packages/django/views/decorators/csrf.py", line 54, in wrapped_view
    return view_func(*args, **kwargs)
  File "/home/telegrambot/.local/share/virtualenvs/AutoApp-g0zIqH6I/lib/python3.8/site-packages/django/views/generic/base.py", line 70, in view
    return self.dispatch(request, *args, **kwargs)
  File "/home/telegrambot/.local/share/virtualenvs/AutoApp-g0zIqH6I/lib/python3.8/site-packages/rest_framework/views.py", line 509, in dispatch
    response = self.handle_exception(exc)
  File "/home/telegrambot/.local/share/virtualenvs/AutoApp-g0zIqH6I/lib/python3.8/site-packages/rest_framework/views.py", line 469, in handle_exception
    self.raise_uncaught_exception(exc)
  File "/home/telegrambot/.local/share/virtualenvs/AutoApp-g0zIqH6I/lib/python3.8/site-packages/rest_framework/views.py", line 480, in raise_uncaught_exception
    raise exc
  File "/home/telegrambot/.local/share/virtualenvs/AutoApp-g0zIqH6I/lib/python3.8/site-packages/rest_framework/views.py", line 506, in dispatch
    response = handler(request, *args, **kwargs)
  File "/home/telegrambot/AutoApp/Auth/views.py", line 175, in get
    return Response(serializer.data)
  File "/home/telegrambot/.local/share/virtualenvs/AutoApp-g0zIqH6I/lib/python3.8/site-packages/rest_framework/serializers.py", line 745, in data
    ret = super().data
  File "/home/telegrambot/.local/share/virtualenvs/AutoApp-g0zIqH6I/lib/python3.8/site-packages/rest_framework/serializers.py", line 246, in data
    self._data = self.to_representation(self.instance)
  File "/home/telegrambot/.local/share/virtualenvs/AutoApp-g0zIqH6I/lib/python3.8/site-packages/rest_framework/serializers.py", line 663, in to_representation
    return [
  File "/home/telegrambot/.local/share/virtualenvs/AutoApp-g0zIqH6I/lib/python3.8/site-packages/django/db/models/query.py", line 287, in __iter__
    self._fetch_all()
  File "/home/telegrambot/.local/share/virtualenvs/AutoApp-g0zIqH6I/lib/python3.8/site-packages/django/db/models/query.py", line 1308, in _fetch_all
    self._result_cache = list(self._iterable_class(self))
  File "/home/telegrambot/.local/share/virtualenvs/AutoApp-g0zIqH6I/lib/python3.8/site-packages/django/db/models/query.py", line 53, in __iter__
    results = compiler.execute_sql(chunked_fetch=self.chunked_fetch, chunk_size=self.chunk_size)
  File "/home/telegrambot/.local/share/virtualenvs/AutoApp-g0zIqH6I/lib/python3.8/site-packages/django/db/models/sql/compiler.py", line 1156, in execute_sql
    cursor.execute(sql, params)
  File "/home/telegrambot/.local/share/virtualenvs/AutoApp-g0zIqH6I/lib/python3.8/site-packages/django/db/backends/utils.py", line 98, in execute
    return super().execute(sql, params)
  File "/home/telegrambot/.local/share/virtualenvs/AutoApp-g0zIqH6I/lib/python3.8/site-packages/django/db/backends/utils.py", line 66, in execute
    return self._execute_with_wrappers(sql, params, many=False, executor=self._execute)
  File "/home/telegrambot/.local/share/virtualenvs/AutoApp-g0zIqH6I/lib/python3.8/site-packages/django/db/backends/utils.py", line 75, in _execute_with_wrappers
    return executor(sql, params, many, context)
  File "/home/telegrambot/.local/share/virtualenvs/AutoApp-g0zIqH6I/lib/python3.8/site-packages/django/db/backends/utils.py", line 84, in _execute
    return self.cursor.execute(sql, params)
  File "/home/telegrambot/.local/share/virtualenvs/AutoApp-g0zIqH6I/lib/python3.8/site-packages/django/db/utils.py", line 90, in __exit__
    raise dj_exc_value.with_traceback(traceback) from exc_value
  File "/home/telegrambot/.local/share/virtualenvs/AutoApp-g0zIqH6I/lib/python3.8/site-packages/django/db/backends/utils.py", line 84, in _execute
    return self.cursor.execute(sql, params)
  File "/home/telegrambot/.local/share/virtualenvs/AutoApp-g0zIqH6I/lib/python3.8/site-packages/django/db/backends/sqlite3/base.py", line 413, in execute
    return Database.Cursor.execute(self, query, params)
django.db.utils.OperationalError: no such table: Auth_usertransport
[2021-02-02 04:00:02 +0000] [17776] [INFO] Worker exiting (pid: 17776)
[2021-02-02 04:00:02 +0000] [17629] [INFO] Handling signal: term
[2021-02-02 04:00:02 +0000] [17629] [INFO] Shutting down: Master
[2021-02-02 04:00:26 +0000] [32673] [INFO] Starting gunicorn 20.0.4
[2021-02-02 04:00:26 +0000] [32673] [INFO] Listening at: http://127.0.0.1:33333 (32673)
[2021-02-02 04:00:26 +0000] [32673] [INFO] Using worker: sync
[2021-02-02 04:00:26 +0000] [340] [INFO] Booting worker with pid: 340
[2021-02-02 10:38:29 +0000] [340] [INFO] Worker exiting (pid: 340)
[2021-02-02 10:38:29 +0000] [32673] [INFO] Handling signal: term
[2021-02-02 10:38:30 +0000] [32673] [INFO] Shutting down: Master
[2021-02-02 10:38:31 +0000] [13571] [INFO] Starting gunicorn 20.0.4
[2021-02-02 10:38:31 +0000] [13571] [INFO] Listening at: http://127.0.0.1:33333 (13571)
[2021-02-02 10:38:31 +0000] [13571] [INFO] Using worker: sync
[2021-02-02 10:38:31 +0000] [13578] [INFO] Booting worker with pid: 13578
Internal Server Error: /authgoogle/
Traceback (most recent call last):
  File "/home/telegrambot/.local/share/virtualenvs/AutoApp-g0zIqH6I/lib/python3.8/site-packages/django/core/handlers/exception.py", line 47, in inner
    response = get_response(request)
  File "/home/telegrambot/.local/share/virtualenvs/AutoApp-g0zIqH6I/lib/python3.8/site-packages/django/core/handlers/base.py", line 179, in _get_response
    response = wrapped_callback(request, *callback_args, **callback_kwargs)
  File "/home/telegrambot/AutoApp/Auth/views.py", line 121, in authGoogle
    redirection = "https://autoapp.page.link/?link=https://autoapp.page.link{}?emailOrPhone={}&date={}&apn=com.autoapp.application&amv=0&afl=google.com".format(direction,validation[0]['emailOrPhone'],validation[0]['date'])
KeyError: 'date'
Not Found: /favicon.ico
Not Found: /favicon.ico
[2021-02-02 14:35:21 +0000] [13578] [INFO] Worker exiting (pid: 13578)
[2021-02-02 14:35:21 +0000] [13571] [INFO] Handling signal: term
[2021-02-02 14:35:21 +0000] [13571] [INFO] Shutting down: Master
[2021-02-02 14:35:23 +0000] [20873] [INFO] Starting gunicorn 20.0.4
[2021-02-02 14:35:23 +0000] [20873] [INFO] Listening at: http://127.0.0.1:33333 (20873)
[2021-02-02 14:35:23 +0000] [20873] [INFO] Using worker: sync
[2021-02-02 14:35:23 +0000] [20881] [INFO] Booting worker with pid: 20881
Internal Server Error: /units/null/
Traceback (most recent call last):
  File "/home/telegrambot/.local/share/virtualenvs/AutoApp-g0zIqH6I/lib/python3.8/site-packages/django/core/handlers/exception.py", line 47, in inner
    response = get_response(request)
  File "/home/telegrambot/.local/share/virtualenvs/AutoApp-g0zIqH6I/lib/python3.8/site-packages/django/core/handlers/base.py", line 179, in _get_response
    response = wrapped_callback(request, *callback_args, **callback_kwargs)
  File "/home/telegrambot/.local/share/virtualenvs/AutoApp-g0zIqH6I/lib/python3.8/site-packages/django/views/decorators/csrf.py", line 54, in wrapped_view
    return view_func(*args, **kwargs)
  File "/home/telegrambot/.local/share/virtualenvs/AutoApp-g0zIqH6I/lib/python3.8/site-packages/django/views/generic/base.py", line 70, in view
    return self.dispatch(request, *args, **kwargs)
  File "/home/telegrambot/.local/share/virtualenvs/AutoApp-g0zIqH6I/lib/python3.8/site-packages/rest_framework/views.py", line 509, in dispatch
    response = self.handle_exception(exc)
  File "/home/telegrambot/.local/share/virtualenvs/AutoApp-g0zIqH6I/lib/python3.8/site-packages/rest_framework/views.py", line 469, in handle_exception
    self.raise_uncaught_exception(exc)
  File "/home/telegrambot/.local/share/virtualenvs/AutoApp-g0zIqH6I/lib/python3.8/site-packages/rest_framework/views.py", line 480, in raise_uncaught_exception
    raise exc
  File "/home/telegrambot/.local/share/virtualenvs/AutoApp-g0zIqH6I/lib/python3.8/site-packages/rest_framework/views.py", line 506, in dispatch
    response = handler(request, *args, **kwargs)
  File "/home/telegrambot/AutoApp/Auth/views.py", line 154, in put
    user = UserTransport.objects.get(emailOrPhone=pk)
  File "/home/telegrambot/.local/share/virtualenvs/AutoApp-g0zIqH6I/lib/python3.8/site-packages/django/db/models/manager.py", line 85, in manager_method
    return getattr(self.get_queryset(), name)(*args, **kwargs)
  File "/home/telegrambot/.local/share/virtualenvs/AutoApp-g0zIqH6I/lib/python3.8/site-packages/django/db/models/query.py", line 429, in get
    raise self.model.DoesNotExist(
Auth.models.UserTransport.DoesNotExist: UserTransport matching query does not exist.
Not Found: /favicon.ico
Internal Server Error: /admin/Auth/modelregister/add/
Traceback (most recent call last):
  File "/home/telegrambot/.local/share/virtualenvs/AutoApp-g0zIqH6I/lib/python3.8/site-packages/django/core/handlers/exception.py", line 47, in inner
    response = get_response(request)
  File "/home/telegrambot/.local/share/virtualenvs/AutoApp-g0zIqH6I/lib/python3.8/site-packages/django/core/handlers/base.py", line 179, in _get_response
    response = wrapped_callback(request, *callback_args, **callback_kwargs)
  File "/home/telegrambot/.local/share/virtualenvs/AutoApp-g0zIqH6I/lib/python3.8/site-packages/django/contrib/admin/options.py", line 614, in wrapper
    return self.admin_site.admin_view(view)(*args, **kwargs)
  File "/home/telegrambot/.local/share/virtualenvs/AutoApp-g0zIqH6I/lib/python3.8/site-packages/django/utils/decorators.py", line 130, in _wrapped_view
    response = view_func(request, *args, **kwargs)
  File "/home/telegrambot/.local/share/virtualenvs/AutoApp-g0zIqH6I/lib/python3.8/site-packages/django/views/decorators/cache.py", line 44, in _wrapped_view_func
    response = view_func(request, *args, **kwargs)
  File "/home/telegrambot/.local/share/virtualenvs/AutoApp-g0zIqH6I/lib/python3.8/site-packages/django/contrib/admin/sites.py", line 233, in inner
    return view(request, *args, **kwargs)
  File "/home/telegrambot/.local/share/virtualenvs/AutoApp-g0zIqH6I/lib/python3.8/site-packages/django/contrib/admin/options.py", line 1653, in add_view
    return self.changeform_view(request, None, form_url, extra_context)
  File "/home/telegrambot/.local/share/virtualenvs/AutoApp-g0zIqH6I/lib/python3.8/site-packages/django/utils/decorators.py", line 43, in _wrapper
    return bound_method(*args, **kwargs)
  File "/home/telegrambot/.local/share/virtualenvs/AutoApp-g0zIqH6I/lib/python3.8/site-packages/django/utils/decorators.py", line 130, in _wrapped_view
    response = view_func(request, *args, **kwargs)
  File "/home/telegrambot/.local/share/virtualenvs/AutoApp-g0zIqH6I/lib/python3.8/site-packages/django/contrib/admin/options.py", line 1534, in changeform_view
    return self._changeform_view(request, object_id, form_url, extra_context)
  File "/home/telegrambot/.local/share/virtualenvs/AutoApp-g0zIqH6I/lib/python3.8/site-packages/django/contrib/admin/options.py", line 1573, in _changeform_view
    form_validated = form.is_valid()
  File "/home/telegrambot/.local/share/virtualenvs/AutoApp-g0zIqH6I/lib/python3.8/site-packages/django/forms/forms.py", line 177, in is_valid
    return self.is_bound and not self.errors
  File "/home/telegrambot/.local/share/virtualenvs/AutoApp-g0zIqH6I/lib/python3.8/site-packages/django/forms/forms.py", line 172, in errors
    self.full_clean()
  File "/home/telegrambot/.local/share/virtualenvs/AutoApp-g0zIqH6I/lib/python3.8/site-packages/django/forms/forms.py", line 374, in full_clean
    self._clean_fields()
  File "/home/telegrambot/.local/share/virtualenvs/AutoApp-g0zIqH6I/lib/python3.8/site-packages/django/forms/forms.py", line 390, in _clean_fields
    value = field.clean(value, initial)
  File "/home/telegrambot/.local/share/virtualenvs/AutoApp-g0zIqH6I/lib/python3.8/site-packages/django/forms/fields.py", line 598, in clean
    return super().clean(data)
  File "/home/telegrambot/.local/share/virtualenvs/AutoApp-g0zIqH6I/lib/python3.8/site-packages/django/forms/fields.py", line 149, in clean
    value = self.to_python(value)
  File "/home/telegrambot/.local/share/virtualenvs/AutoApp-g0zIqH6I/lib/python3.8/site-packages/django/forms/fields.py", line 627, in to_python
    from PIL import Image
ModuleNotFoundError: No module named 'PIL'
Internal Server Error: /admin/Auth/modelregister/add/
Traceback (most recent call last):
  File "/home/telegrambot/.local/share/virtualenvs/AutoApp-g0zIqH6I/lib/python3.8/site-packages/django/core/handlers/exception.py", line 47, in inner
    response = get_response(request)
  File "/home/telegrambot/.local/share/virtualenvs/AutoApp-g0zIqH6I/lib/python3.8/site-packages/django/core/handlers/base.py", line 179, in _get_response
    response = wrapped_callback(request, *callback_args, **callback_kwargs)
  File "/home/telegrambot/.local/share/virtualenvs/AutoApp-g0zIqH6I/lib/python3.8/site-packages/django/contrib/admin/options.py", line 614, in wrapper
    return self.admin_site.admin_view(view)(*args, **kwargs)
  File "/home/telegrambot/.local/share/virtualenvs/AutoApp-g0zIqH6I/lib/python3.8/site-packages/django/utils/decorators.py", line 130, in _wrapped_view
    response = view_func(request, *args, **kwargs)
  File "/home/telegrambot/.local/share/virtualenvs/AutoApp-g0zIqH6I/lib/python3.8/site-packages/django/views/decorators/cache.py", line 44, in _wrapped_view_func
    response = view_func(request, *args, **kwargs)
  File "/home/telegrambot/.local/share/virtualenvs/AutoApp-g0zIqH6I/lib/python3.8/site-packages/django/contrib/admin/sites.py", line 233, in inner
    return view(request, *args, **kwargs)
  File "/home/telegrambot/.local/share/virtualenvs/AutoApp-g0zIqH6I/lib/python3.8/site-packages/django/contrib/admin/options.py", line 1653, in add_view
    return self.changeform_view(request, None, form_url, extra_context)
  File "/home/telegrambot/.local/share/virtualenvs/AutoApp-g0zIqH6I/lib/python3.8/site-packages/django/utils/decorators.py", line 43, in _wrapper
    return bound_method(*args, **kwargs)
  File "/home/telegrambot/.local/share/virtualenvs/AutoApp-g0zIqH6I/lib/python3.8/site-packages/django/utils/decorators.py", line 130, in _wrapped_view
    response = view_func(request, *args, **kwargs)
  File "/home/telegrambot/.local/share/virtualenvs/AutoApp-g0zIqH6I/lib/python3.8/site-packages/django/contrib/admin/options.py", line 1534, in changeform_view
    return self._changeform_view(request, object_id, form_url, extra_context)
  File "/home/telegrambot/.local/share/virtualenvs/AutoApp-g0zIqH6I/lib/python3.8/site-packages/django/contrib/admin/options.py", line 1573, in _changeform_view
    form_validated = form.is_valid()
  File "/home/telegrambot/.local/share/virtualenvs/AutoApp-g0zIqH6I/lib/python3.8/site-packages/django/forms/forms.py", line 177, in is_valid
    return self.is_bound and not self.errors
  File "/home/telegrambot/.local/share/virtualenvs/AutoApp-g0zIqH6I/lib/python3.8/site-packages/django/forms/forms.py", line 172, in errors
    self.full_clean()
  File "/home/telegrambot/.local/share/virtualenvs/AutoApp-g0zIqH6I/lib/python3.8/site-packages/django/forms/forms.py", line 374, in full_clean
    self._clean_fields()
  File "/home/telegrambot/.local/share/virtualenvs/AutoApp-g0zIqH6I/lib/python3.8/site-packages/django/forms/forms.py", line 390, in _clean_fields
    value = field.clean(value, initial)
  File "/home/telegrambot/.local/share/virtualenvs/AutoApp-g0zIqH6I/lib/python3.8/site-packages/django/forms/fields.py", line 598, in clean
    return super().clean(data)
  File "/home/telegrambot/.local/share/virtualenvs/AutoApp-g0zIqH6I/lib/python3.8/site-packages/django/forms/fields.py", line 149, in clean
    value = self.to_python(value)
  File "/home/telegrambot/.local/share/virtualenvs/AutoApp-g0zIqH6I/lib/python3.8/site-packages/django/forms/fields.py", line 627, in to_python
    from PIL import Image
ModuleNotFoundError: No module named 'PIL'
[2021-02-02 14:53:47 +0000] [20881] [INFO] Worker exiting (pid: 20881)
[2021-02-02 14:53:47 +0000] [20873] [INFO] Handling signal: term
[2021-02-02 14:53:47 +0000] [20873] [INFO] Shutting down: Master
[2021-02-02 14:53:49 +0000] [21483] [INFO] Starting gunicorn 20.0.4
[2021-02-02 14:53:49 +0000] [21483] [INFO] Listening at: http://127.0.0.1:33333 (21483)
[2021-02-02 14:53:49 +0000] [21483] [INFO] Using worker: sync
[2021-02-02 14:53:49 +0000] [21490] [INFO] Booting worker with pid: 21490
Internal Server Error: /transport/agag@ga.yz/
Traceback (most recent call last):
  File "/home/telegrambot/.local/share/virtualenvs/AutoApp-g0zIqH6I/lib/python3.8/site-packages/django/db/models/fields/__init__.py", line 1774, in get_prep_value
    return int(value)
ValueError: invalid literal for int() with base 10: 'agag@ga.yz'

The above exception was the direct cause of the following exception:

Traceback (most recent call last):
  File "/home/telegrambot/.local/share/virtualenvs/AutoApp-g0zIqH6I/lib/python3.8/site-packages/django/core/handlers/exception.py", line 47, in inner
    response = get_response(request)
  File "/home/telegrambot/.local/share/virtualenvs/AutoApp-g0zIqH6I/lib/python3.8/site-packages/django/core/handlers/base.py", line 179, in _get_response
    response = wrapped_callback(request, *callback_args, **callback_kwargs)
  File "/home/telegrambot/.local/share/virtualenvs/AutoApp-g0zIqH6I/lib/python3.8/site-packages/django/views/decorators/csrf.py", line 54, in wrapped_view
    return view_func(*args, **kwargs)
  File "/home/telegrambot/.local/share/virtualenvs/AutoApp-g0zIqH6I/lib/python3.8/site-packages/django/views/generic/base.py", line 70, in view
    return self.dispatch(request, *args, **kwargs)
  File "/home/telegrambot/.local/share/virtualenvs/AutoApp-g0zIqH6I/lib/python3.8/site-packages/rest_framework/views.py", line 509, in dispatch
    response = self.handle_exception(exc)
  File "/home/telegrambot/.local/share/virtualenvs/AutoApp-g0zIqH6I/lib/python3.8/site-packages/rest_framework/views.py", line 469, in handle_exception
    self.raise_uncaught_exception(exc)
  File "/home/telegrambot/.local/share/virtualenvs/AutoApp-g0zIqH6I/lib/python3.8/site-packages/rest_framework/views.py", line 480, in raise_uncaught_exception
    raise exc
  File "/home/telegrambot/.local/share/virtualenvs/AutoApp-g0zIqH6I/lib/python3.8/site-packages/rest_framework/views.py", line 506, in dispatch
    response = handler(request, *args, **kwargs)
  File "/home/telegrambot/AutoApp/Auth/views.py", line 231, in put
    detail =  TransportDetail.objects.get(id = pk)
  File "/home/telegrambot/.local/share/virtualenvs/AutoApp-g0zIqH6I/lib/python3.8/site-packages/django/db/models/manager.py", line 85, in manager_method
    return getattr(self.get_queryset(), name)(*args, **kwargs)
  File "/home/telegrambot/.local/share/virtualenvs/AutoApp-g0zIqH6I/lib/python3.8/site-packages/django/db/models/query.py", line 418, in get
    clone = self._chain() if self.query.combinator else self.filter(*args, **kwargs)
  File "/home/telegrambot/.local/share/virtualenvs/AutoApp-g0zIqH6I/lib/python3.8/site-packages/django/db/models/query.py", line 942, in filter
    return self._filter_or_exclude(False, *args, **kwargs)
  File "/home/telegrambot/.local/share/virtualenvs/AutoApp-g0zIqH6I/lib/python3.8/site-packages/django/db/models/query.py", line 962, in _filter_or_exclude
    clone._filter_or_exclude_inplace(negate, *args, **kwargs)
  File "/home/telegrambot/.local/share/virtualenvs/AutoApp-g0zIqH6I/lib/python3.8/site-packages/django/db/models/query.py", line 969, in _filter_or_exclude_inplace
    self._query.add_q(Q(*args, **kwargs))
  File "/home/telegrambot/.local/share/virtualenvs/AutoApp-g0zIqH6I/lib/python3.8/site-packages/django/db/models/sql/query.py", line 1358, in add_q
    clause, _ = self._add_q(q_object, self.used_aliases)
  File "/home/telegrambot/.local/share/virtualenvs/AutoApp-g0zIqH6I/lib/python3.8/site-packages/django/db/models/sql/query.py", line 1377, in _add_q
    child_clause, needed_inner = self.build_filter(
  File "/home/telegrambot/.local/share/virtualenvs/AutoApp-g0zIqH6I/lib/python3.8/site-packages/django/db/models/sql/query.py", line 1319, in build_filter
    condition = self.build_lookup(lookups, col, value)
  File "/home/telegrambot/.local/share/virtualenvs/AutoApp-g0zIqH6I/lib/python3.8/site-packages/django/db/models/sql/query.py", line 1165, in build_lookup
    lookup = lookup_class(lhs, rhs)
  File "/home/telegrambot/.local/share/virtualenvs/AutoApp-g0zIqH6I/lib/python3.8/site-packages/django/db/models/lookups.py", line 24, in __init__
    self.rhs = self.get_prep_lookup()
  File "/home/telegrambot/.local/share/virtualenvs/AutoApp-g0zIqH6I/lib/python3.8/site-packages/django/db/models/lookups.py", line 76, in get_prep_lookup
    return self.lhs.output_field.get_prep_value(self.rhs)
  File "/home/telegrambot/.local/share/virtualenvs/AutoApp-g0zIqH6I/lib/python3.8/site-packages/django/db/models/fields/__init__.py", line 1776, in get_prep_value
    raise e.__class__(
ValueError: Field 'id' expected a number but got 'agag@ga.yz'.
Not Found: /favicon.ico
Internal Server Error: /transport/
Traceback (most recent call last):
  File "/home/telegrambot/.local/share/virtualenvs/AutoApp-g0zIqH6I/lib/python3.8/site-packages/django/core/handlers/exception.py", line 47, in inner
    response = get_response(request)
  File "/home/telegrambot/.local/share/virtualenvs/AutoApp-g0zIqH6I/lib/python3.8/site-packages/django/core/handlers/base.py", line 179, in _get_response
    response = wrapped_callback(request, *callback_args, **callback_kwargs)
  File "/home/telegrambot/.local/share/virtualenvs/AutoApp-g0zIqH6I/lib/python3.8/site-packages/django/views/decorators/csrf.py", line 54, in wrapped_view
    return view_func(*args, **kwargs)
  File "/home/telegrambot/.local/share/virtualenvs/AutoApp-g0zIqH6I/lib/python3.8/site-packages/django/views/generic/base.py", line 70, in view
    return self.dispatch(request, *args, **kwargs)
  File "/home/telegrambot/.local/share/virtualenvs/AutoApp-g0zIqH6I/lib/python3.8/site-packages/rest_framework/views.py", line 509, in dispatch
    response = self.handle_exception(exc)
  File "/home/telegrambot/.local/share/virtualenvs/AutoApp-g0zIqH6I/lib/python3.8/site-packages/rest_framework/views.py", line 469, in handle_exception
    self.raise_uncaught_exception(exc)
  File "/home/telegrambot/.local/share/virtualenvs/AutoApp-g0zIqH6I/lib/python3.8/site-packages/rest_framework/views.py", line 480, in raise_uncaught_exception
    raise exc
  File "/home/telegrambot/.local/share/virtualenvs/AutoApp-g0zIqH6I/lib/python3.8/site-packages/rest_framework/views.py", line 506, in dispatch
    response = handler(request, *args, **kwargs)
  File "/home/telegrambot/AutoApp/Auth/views.py", line 201, in get
    return Response({"cards":detail.data, "date": user.date ,"units":units.data})
UnboundLocalError: local variable 'detail' referenced before assignment
Internal Server Error: /transport/
Traceback (most recent call last):
  File "/home/telegrambot/.local/share/virtualenvs/AutoApp-g0zIqH6I/lib/python3.8/site-packages/django/core/handlers/exception.py", line 47, in inner
    response = get_response(request)
  File "/home/telegrambot/.local/share/virtualenvs/AutoApp-g0zIqH6I/lib/python3.8/site-packages/django/core/handlers/base.py", line 179, in _get_response
    response = wrapped_callback(request, *callback_args, **callback_kwargs)
  File "/home/telegrambot/.local/share/virtualenvs/AutoApp-g0zIqH6I/lib/python3.8/site-packages/django/views/decorators/csrf.py", line 54, in wrapped_view
    return view_func(*args, **kwargs)
  File "/home/telegrambot/.local/share/virtualenvs/AutoApp-g0zIqH6I/lib/python3.8/site-packages/django/views/generic/base.py", line 70, in view
    return self.dispatch(request, *args, **kwargs)
  File "/home/telegrambot/.local/share/virtualenvs/AutoApp-g0zIqH6I/lib/python3.8/site-packages/rest_framework/views.py", line 509, in dispatch
    response = self.handle_exception(exc)
  File "/home/telegrambot/.local/share/virtualenvs/AutoApp-g0zIqH6I/lib/python3.8/site-packages/rest_framework/views.py", line 469, in handle_exception
    self.raise_uncaught_exception(exc)
  File "/home/telegrambot/.local/share/virtualenvs/AutoApp-g0zIqH6I/lib/python3.8/site-packages/rest_framework/views.py", line 480, in raise_uncaught_exception
    raise exc
  File "/home/telegrambot/.local/share/virtualenvs/AutoApp-g0zIqH6I/lib/python3.8/site-packages/rest_framework/views.py", line 506, in dispatch
    response = handler(request, *args, **kwargs)
  File "/home/telegrambot/AutoApp/Auth/views.py", line 201, in get
    return Response({"cards":detail.data, "date": user.date ,"units":units.data})
UnboundLocalError: local variable 'detail' referenced before assignment
Internal Server Error: /transport/1/
Traceback (most recent call last):
  File "/home/telegrambot/.local/share/virtualenvs/AutoApp-g0zIqH6I/lib/python3.8/site-packages/django/core/handlers/exception.py", line 47, in inner
    response = get_response(request)
  File "/home/telegrambot/.local/share/virtualenvs/AutoApp-g0zIqH6I/lib/python3.8/site-packages/django/core/handlers/base.py", line 179, in _get_response
    response = wrapped_callback(request, *callback_args, **callback_kwargs)
  File "/home/telegrambot/.local/share/virtualenvs/AutoApp-g0zIqH6I/lib/python3.8/site-packages/django/views/decorators/csrf.py", line 54, in wrapped_view
    return view_func(*args, **kwargs)
  File "/home/telegrambot/.local/share/virtualenvs/AutoApp-g0zIqH6I/lib/python3.8/site-packages/django/views/generic/base.py", line 70, in view
    return self.dispatch(request, *args, **kwargs)
  File "/home/telegrambot/.local/share/virtualenvs/AutoApp-g0zIqH6I/lib/python3.8/site-packages/rest_framework/views.py", line 509, in dispatch
    response = self.handle_exception(exc)
  File "/home/telegrambot/.local/share/virtualenvs/AutoApp-g0zIqH6I/lib/python3.8/site-packages/rest_framework/views.py", line 469, in handle_exception
    self.raise_uncaught_exception(exc)
  File "/home/telegrambot/.local/share/virtualenvs/AutoApp-g0zIqH6I/lib/python3.8/site-packages/rest_framework/views.py", line 480, in raise_uncaught_exception
    raise exc
  File "/home/telegrambot/.local/share/virtualenvs/AutoApp-g0zIqH6I/lib/python3.8/site-packages/rest_framework/views.py", line 506, in dispatch
    response = handler(request, *args, **kwargs)
  File "/home/telegrambot/AutoApp/Auth/views.py", line 198, in get
    user = UserTransport.objects.get(emailOrPhone=kwargs['pk'])
  File "/home/telegrambot/.local/share/virtualenvs/AutoApp-g0zIqH6I/lib/python3.8/site-packages/django/db/models/manager.py", line 85, in manager_method
    return getattr(self.get_queryset(), name)(*args, **kwargs)
  File "/home/telegrambot/.local/share/virtualenvs/AutoApp-g0zIqH6I/lib/python3.8/site-packages/django/db/models/query.py", line 429, in get
    raise self.model.DoesNotExist(
Auth.models.UserTransport.DoesNotExist: UserTransport matching query does not exist.
Not Found: /
Internal Server Error: /transport/
Traceback (most recent call last):
  File "/home/telegrambot/.local/share/virtualenvs/AutoApp-g0zIqH6I/lib/python3.8/site-packages/django/core/handlers/exception.py", line 47, in inner
    response = get_response(request)
  File "/home/telegrambot/.local/share/virtualenvs/AutoApp-g0zIqH6I/lib/python3.8/site-packages/django/core/handlers/base.py", line 179, in _get_response
    response = wrapped_callback(request, *callback_args, **callback_kwargs)
  File "/home/telegrambot/.local/share/virtualenvs/AutoApp-g0zIqH6I/lib/python3.8/site-packages/django/views/decorators/csrf.py", line 54, in wrapped_view
    return view_func(*args, **kwargs)
  File "/home/telegrambot/.local/share/virtualenvs/AutoApp-g0zIqH6I/lib/python3.8/site-packages/django/views/generic/base.py", line 70, in view
    return self.dispatch(request, *args, **kwargs)
  File "/home/telegrambot/.local/share/virtualenvs/AutoApp-g0zIqH6I/lib/python3.8/site-packages/rest_framework/views.py", line 509, in dispatch
    response = self.handle_exception(exc)
  File "/home/telegrambot/.local/share/virtualenvs/AutoApp-g0zIqH6I/lib/python3.8/site-packages/rest_framework/views.py", line 469, in handle_exception
    self.raise_uncaught_exception(exc)
  File "/home/telegrambot/.local/share/virtualenvs/AutoApp-g0zIqH6I/lib/python3.8/site-packages/rest_framework/views.py", line 480, in raise_uncaught_exception
    raise exc
  File "/home/telegrambot/.local/share/virtualenvs/AutoApp-g0zIqH6I/lib/python3.8/site-packages/rest_framework/views.py", line 506, in dispatch
    response = handler(request, *args, **kwargs)
  File "/home/telegrambot/AutoApp/Auth/views.py", line 201, in get
    return Response({"cards":detail.data, "date": user.date ,"units":units.data})
UnboundLocalError: local variable 'detail' referenced before assignment
Internal Server Error: /admin/
Traceback (most recent call last):
  File "/home/telegrambot/.local/share/virtualenvs/AutoApp-g0zIqH6I/lib/python3.8/site-packages/django/contrib/sessions/backends/base.py", line 233, in _get_session
    return self._session_cache
AttributeError: 'SessionStore' object has no attribute '_session_cache'

During handling of the above exception, another exception occurred:

Traceback (most recent call last):
  File "/home/telegrambot/.local/share/virtualenvs/AutoApp-g0zIqH6I/lib/python3.8/site-packages/django/db/backends/utils.py", line 84, in _execute
    return self.cursor.execute(sql, params)
  File "/home/telegrambot/.local/share/virtualenvs/AutoApp-g0zIqH6I/lib/python3.8/site-packages/django/db/backends/sqlite3/base.py", line 413, in execute
    return Database.Cursor.execute(self, query, params)
sqlite3.OperationalError: no such table: django_session

The above exception was the direct cause of the following exception:

Traceback (most recent call last):
  File "/home/telegrambot/.local/share/virtualenvs/AutoApp-g0zIqH6I/lib/python3.8/site-packages/django/core/handlers/exception.py", line 47, in inner
    response = get_response(request)
  File "/home/telegrambot/.local/share/virtualenvs/AutoApp-g0zIqH6I/lib/python3.8/site-packages/django/core/handlers/base.py", line 179, in _get_response
    response = wrapped_callback(request, *callback_args, **callback_kwargs)
  File "/home/telegrambot/.local/share/virtualenvs/AutoApp-g0zIqH6I/lib/python3.8/site-packages/django/contrib/admin/sites.py", line 251, in wrapper
    return self.admin_view(view, cacheable)(*args, **kwargs)
  File "/home/telegrambot/.local/share/virtualenvs/AutoApp-g0zIqH6I/lib/python3.8/site-packages/django/utils/decorators.py", line 130, in _wrapped_view
    response = view_func(request, *args, **kwargs)
  File "/home/telegrambot/.local/share/virtualenvs/AutoApp-g0zIqH6I/lib/python3.8/site-packages/django/views/decorators/cache.py", line 44, in _wrapped_view_func
    response = view_func(request, *args, **kwargs)
  File "/home/telegrambot/.local/share/virtualenvs/AutoApp-g0zIqH6I/lib/python3.8/site-packages/django/contrib/admin/sites.py", line 222, in inner
    if not self.has_permission(request):
  File "/home/telegrambot/.local/share/virtualenvs/AutoApp-g0zIqH6I/lib/python3.8/site-packages/django/contrib/admin/sites.py", line 196, in has_permission
    return request.user.is_active and request.user.is_staff
  File "/home/telegrambot/.local/share/virtualenvs/AutoApp-g0zIqH6I/lib/python3.8/site-packages/django/utils/functional.py", line 240, in inner
    self._setup()
  File "/home/telegrambot/.local/share/virtualenvs/AutoApp-g0zIqH6I/lib/python3.8/site-packages/django/utils/functional.py", line 376, in _setup
    self._wrapped = self._setupfunc()
  File "/home/telegrambot/.local/share/virtualenvs/AutoApp-g0zIqH6I/lib/python3.8/site-packages/django/contrib/auth/middleware.py", line 23, in <lambda>
    request.user = SimpleLazyObject(lambda: get_user(request))
  File "/home/telegrambot/.local/share/virtualenvs/AutoApp-g0zIqH6I/lib/python3.8/site-packages/django/contrib/auth/middleware.py", line 11, in get_user
    request._cached_user = auth.get_user(request)
  File "/home/telegrambot/.local/share/virtualenvs/AutoApp-g0zIqH6I/lib/python3.8/site-packages/django/contrib/auth/__init__.py", line 174, in get_user
    user_id = _get_user_session_key(request)
  File "/home/telegrambot/.local/share/virtualenvs/AutoApp-g0zIqH6I/lib/python3.8/site-packages/django/contrib/auth/__init__.py", line 58, in _get_user_session_key
    return get_user_model()._meta.pk.to_python(request.session[SESSION_KEY])
  File "/home/telegrambot/.local/share/virtualenvs/AutoApp-g0zIqH6I/lib/python3.8/site-packages/django/contrib/sessions/backends/base.py", line 65, in __getitem__
    return self._session[key]
  File "/home/telegrambot/.local/share/virtualenvs/AutoApp-g0zIqH6I/lib/python3.8/site-packages/django/contrib/sessions/backends/base.py", line 238, in _get_session
    self._session_cache = self.load()
  File "/home/telegrambot/.local/share/virtualenvs/AutoApp-g0zIqH6I/lib/python3.8/site-packages/django/contrib/sessions/backends/db.py", line 43, in load
    s = self._get_session_from_db()
  File "/home/telegrambot/.local/share/virtualenvs/AutoApp-g0zIqH6I/lib/python3.8/site-packages/django/contrib/sessions/backends/db.py", line 32, in _get_session_from_db
    return self.model.objects.get(
  File "/home/telegrambot/.local/share/virtualenvs/AutoApp-g0zIqH6I/lib/python3.8/site-packages/django/db/models/manager.py", line 85, in manager_method
    return getattr(self.get_queryset(), name)(*args, **kwargs)
  File "/home/telegrambot/.local/share/virtualenvs/AutoApp-g0zIqH6I/lib/python3.8/site-packages/django/db/models/query.py", line 425, in get
    num = len(clone)
  File "/home/telegrambot/.local/share/virtualenvs/AutoApp-g0zIqH6I/lib/python3.8/site-packages/django/db/models/query.py", line 269, in __len__
    self._fetch_all()
  File "/home/telegrambot/.local/share/virtualenvs/AutoApp-g0zIqH6I/lib/python3.8/site-packages/django/db/models/query.py", line 1308, in _fetch_all
    self._result_cache = list(self._iterable_class(self))
  File "/home/telegrambot/.local/share/virtualenvs/AutoApp-g0zIqH6I/lib/python3.8/site-packages/django/db/models/query.py", line 53, in __iter__
    results = compiler.execute_sql(chunked_fetch=self.chunked_fetch, chunk_size=self.chunk_size)
  File "/home/telegrambot/.local/share/virtualenvs/AutoApp-g0zIqH6I/lib/python3.8/site-packages/django/db/models/sql/compiler.py", line 1156, in execute_sql
    cursor.execute(sql, params)
  File "/home/telegrambot/.local/share/virtualenvs/AutoApp-g0zIqH6I/lib/python3.8/site-packages/django/db/backends/utils.py", line 98, in execute
    return super().execute(sql, params)
  File "/home/telegrambot/.local/share/virtualenvs/AutoApp-g0zIqH6I/lib/python3.8/site-packages/django/db/backends/utils.py", line 66, in execute
    return self._execute_with_wrappers(sql, params, many=False, executor=self._execute)
  File "/home/telegrambot/.local/share/virtualenvs/AutoApp-g0zIqH6I/lib/python3.8/site-packages/django/db/backends/utils.py", line 75, in _execute_with_wrappers
    return executor(sql, params, many, context)
  File "/home/telegrambot/.local/share/virtualenvs/AutoApp-g0zIqH6I/lib/python3.8/site-packages/django/db/backends/utils.py", line 84, in _execute
    return self.cursor.execute(sql, params)
  File "/home/telegrambot/.local/share/virtualenvs/AutoApp-g0zIqH6I/lib/python3.8/site-packages/django/db/utils.py", line 90, in __exit__
    raise dj_exc_value.with_traceback(traceback) from exc_value
  File "/home/telegrambot/.local/share/virtualenvs/AutoApp-g0zIqH6I/lib/python3.8/site-packages/django/db/backends/utils.py", line 84, in _execute
    return self.cursor.execute(sql, params)
  File "/home/telegrambot/.local/share/virtualenvs/AutoApp-g0zIqH6I/lib/python3.8/site-packages/django/db/backends/sqlite3/base.py", line 413, in execute
    return Database.Cursor.execute(self, query, params)
django.db.utils.OperationalError: no such table: django_session
[2021-02-02 18:12:38 +0000] [21490] [INFO] Worker exiting (pid: 21490)
[2021-02-02 18:12:38 +0000] [21483] [INFO] Handling signal: term
[2021-02-02 18:12:38 +0000] [21483] [INFO] Shutting down: Master
[2021-02-02 18:12:40 +0000] [28716] [INFO] Starting gunicorn 20.0.4
[2021-02-02 18:12:40 +0000] [28716] [INFO] Listening at: http://127.0.0.1:33333 (28716)
[2021-02-02 18:12:40 +0000] [28716] [INFO] Using worker: sync
[2021-02-02 18:12:40 +0000] [28726] [INFO] Booting worker with pid: 28726
Internal Server Error: /units/null/
Traceback (most recent call last):
  File "/home/telegrambot/.local/share/virtualenvs/AutoApp-g0zIqH6I/lib/python3.8/site-packages/django/core/handlers/exception.py", line 47, in inner
    response = get_response(request)
  File "/home/telegrambot/.local/share/virtualenvs/AutoApp-g0zIqH6I/lib/python3.8/site-packages/django/core/handlers/base.py", line 179, in _get_response
    response = wrapped_callback(request, *callback_args, **callback_kwargs)
  File "/home/telegrambot/.local/share/virtualenvs/AutoApp-g0zIqH6I/lib/python3.8/site-packages/django/views/decorators/csrf.py", line 54, in wrapped_view
    return view_func(*args, **kwargs)
  File "/home/telegrambot/.local/share/virtualenvs/AutoApp-g0zIqH6I/lib/python3.8/site-packages/django/views/generic/base.py", line 70, in view
    return self.dispatch(request, *args, **kwargs)
  File "/home/telegrambot/.local/share/virtualenvs/AutoApp-g0zIqH6I/lib/python3.8/site-packages/rest_framework/views.py", line 509, in dispatch
    response = self.handle_exception(exc)
  File "/home/telegrambot/.local/share/virtualenvs/AutoApp-g0zIqH6I/lib/python3.8/site-packages/rest_framework/views.py", line 469, in handle_exception
    self.raise_uncaught_exception(exc)
  File "/home/telegrambot/.local/share/virtualenvs/AutoApp-g0zIqH6I/lib/python3.8/site-packages/rest_framework/views.py", line 480, in raise_uncaught_exception
    raise exc
  File "/home/telegrambot/.local/share/virtualenvs/AutoApp-g0zIqH6I/lib/python3.8/site-packages/rest_framework/views.py", line 506, in dispatch
    response = handler(request, *args, **kwargs)
  File "/home/telegrambot/AutoApp/Auth/views.py", line 154, in put
    user = UserTransport.objects.get(emailOrPhone=pk)
  File "/home/telegrambot/.local/share/virtualenvs/AutoApp-g0zIqH6I/lib/python3.8/site-packages/django/db/models/manager.py", line 85, in manager_method
    return getattr(self.get_queryset(), name)(*args, **kwargs)
  File "/home/telegrambot/.local/share/virtualenvs/AutoApp-g0zIqH6I/lib/python3.8/site-packages/django/db/models/query.py", line 429, in get
    raise self.model.DoesNotExist(
Auth.models.UserTransport.DoesNotExist: UserTransport matching query does not exist.
Internal Server Error: /transport/null/
Traceback (most recent call last):
  File "/home/telegrambot/.local/share/virtualenvs/AutoApp-g0zIqH6I/lib/python3.8/site-packages/django/db/models/fields/__init__.py", line 1774, in get_prep_value
    return int(value)
ValueError: invalid literal for int() with base 10: 'null'

The above exception was the direct cause of the following exception:

Traceback (most recent call last):
  File "/home/telegrambot/.local/share/virtualenvs/AutoApp-g0zIqH6I/lib/python3.8/site-packages/django/core/handlers/exception.py", line 47, in inner
    response = get_response(request)
  File "/home/telegrambot/.local/share/virtualenvs/AutoApp-g0zIqH6I/lib/python3.8/site-packages/django/core/handlers/base.py", line 179, in _get_response
    response = wrapped_callback(request, *callback_args, **callback_kwargs)
  File "/home/telegrambot/.local/share/virtualenvs/AutoApp-g0zIqH6I/lib/python3.8/site-packages/django/views/decorators/csrf.py", line 54, in wrapped_view
    return view_func(*args, **kwargs)
  File "/home/telegrambot/.local/share/virtualenvs/AutoApp-g0zIqH6I/lib/python3.8/site-packages/django/views/generic/base.py", line 70, in view
    return self.dispatch(request, *args, **kwargs)
  File "/home/telegrambot/.local/share/virtualenvs/AutoApp-g0zIqH6I/lib/python3.8/site-packages/rest_framework/views.py", line 509, in dispatch
    response = self.handle_exception(exc)
  File "/home/telegrambot/.local/share/virtualenvs/AutoApp-g0zIqH6I/lib/python3.8/site-packages/rest_framework/views.py", line 469, in handle_exception
    self.raise_uncaught_exception(exc)
  File "/home/telegrambot/.local/share/virtualenvs/AutoApp-g0zIqH6I/lib/python3.8/site-packages/rest_framework/views.py", line 480, in raise_uncaught_exception
    raise exc
  File "/home/telegrambot/.local/share/virtualenvs/AutoApp-g0zIqH6I/lib/python3.8/site-packages/rest_framework/views.py", line 506, in dispatch
    response = handler(request, *args, **kwargs)
  File "/home/telegrambot/AutoApp/Auth/views.py", line 232, in put
    detail =  TransportDetail.objects.get(id = pk)
  File "/home/telegrambot/.local/share/virtualenvs/AutoApp-g0zIqH6I/lib/python3.8/site-packages/django/db/models/manager.py", line 85, in manager_method
    return getattr(self.get_queryset(), name)(*args, **kwargs)
  File "/home/telegrambot/.local/share/virtualenvs/AutoApp-g0zIqH6I/lib/python3.8/site-packages/django/db/models/query.py", line 418, in get
    clone = self._chain() if self.query.combinator else self.filter(*args, **kwargs)
  File "/home/telegrambot/.local/share/virtualenvs/AutoApp-g0zIqH6I/lib/python3.8/site-packages/django/db/models/query.py", line 942, in filter
    return self._filter_or_exclude(False, *args, **kwargs)
  File "/home/telegrambot/.local/share/virtualenvs/AutoApp-g0zIqH6I/lib/python3.8/site-packages/django/db/models/query.py", line 962, in _filter_or_exclude
    clone._filter_or_exclude_inplace(negate, *args, **kwargs)
  File "/home/telegrambot/.local/share/virtualenvs/AutoApp-g0zIqH6I/lib/python3.8/site-packages/django/db/models/query.py", line 969, in _filter_or_exclude_inplace
    self._query.add_q(Q(*args, **kwargs))
  File "/home/telegrambot/.local/share/virtualenvs/AutoApp-g0zIqH6I/lib/python3.8/site-packages/django/db/models/sql/query.py", line 1358, in add_q
    clause, _ = self._add_q(q_object, self.used_aliases)
  File "/home/telegrambot/.local/share/virtualenvs/AutoApp-g0zIqH6I/lib/python3.8/site-packages/django/db/models/sql/query.py", line 1377, in _add_q
    child_clause, needed_inner = self.build_filter(
  File "/home/telegrambot/.local/share/virtualenvs/AutoApp-g0zIqH6I/lib/python3.8/site-packages/django/db/models/sql/query.py", line 1319, in build_filter
    condition = self.build_lookup(lookups, col, value)
  File "/home/telegrambot/.local/share/virtualenvs/AutoApp-g0zIqH6I/lib/python3.8/site-packages/django/db/models/sql/query.py", line 1165, in build_lookup
    lookup = lookup_class(lhs, rhs)
  File "/home/telegrambot/.local/share/virtualenvs/AutoApp-g0zIqH6I/lib/python3.8/site-packages/django/db/models/lookups.py", line 24, in __init__
    self.rhs = self.get_prep_lookup()
  File "/home/telegrambot/.local/share/virtualenvs/AutoApp-g0zIqH6I/lib/python3.8/site-packages/django/db/models/lookups.py", line 76, in get_prep_lookup
    return self.lhs.output_field.get_prep_value(self.rhs)
  File "/home/telegrambot/.local/share/virtualenvs/AutoApp-g0zIqH6I/lib/python3.8/site-packages/django/db/models/fields/__init__.py", line 1776, in get_prep_value
    raise e.__class__(
ValueError: Field 'id' expected a number but got 'null'.
Internal Server Error: /units/null/
Traceback (most recent call last):
  File "/home/telegrambot/.local/share/virtualenvs/AutoApp-g0zIqH6I/lib/python3.8/site-packages/django/core/handlers/exception.py", line 47, in inner
    response = get_response(request)
  File "/home/telegrambot/.local/share/virtualenvs/AutoApp-g0zIqH6I/lib/python3.8/site-packages/django/core/handlers/base.py", line 179, in _get_response
    response = wrapped_callback(request, *callback_args, **callback_kwargs)
  File "/home/telegrambot/.local/share/virtualenvs/AutoApp-g0zIqH6I/lib/python3.8/site-packages/django/views/decorators/csrf.py", line 54, in wrapped_view
    return view_func(*args, **kwargs)
  File "/home/telegrambot/.local/share/virtualenvs/AutoApp-g0zIqH6I/lib/python3.8/site-packages/django/views/generic/base.py", line 70, in view
    return self.dispatch(request, *args, **kwargs)
  File "/home/telegrambot/.local/share/virtualenvs/AutoApp-g0zIqH6I/lib/python3.8/site-packages/rest_framework/views.py", line 509, in dispatch
    response = self.handle_exception(exc)
  File "/home/telegrambot/.local/share/virtualenvs/AutoApp-g0zIqH6I/lib/python3.8/site-packages/rest_framework/views.py", line 469, in handle_exception
    self.raise_uncaught_exception(exc)
  File "/home/telegrambot/.local/share/virtualenvs/AutoApp-g0zIqH6I/lib/python3.8/site-packages/rest_framework/views.py", line 480, in raise_uncaught_exception
    raise exc
  File "/home/telegrambot/.local/share/virtualenvs/AutoApp-g0zIqH6I/lib/python3.8/site-packages/rest_framework/views.py", line 506, in dispatch
    response = handler(request, *args, **kwargs)
  File "/home/telegrambot/AutoApp/Auth/views.py", line 154, in put
    user = UserTransport.objects.get(emailOrPhone=pk)
  File "/home/telegrambot/.local/share/virtualenvs/AutoApp-g0zIqH6I/lib/python3.8/site-packages/django/db/models/manager.py", line 85, in manager_method
    return getattr(self.get_queryset(), name)(*args, **kwargs)
  File "/home/telegrambot/.local/share/virtualenvs/AutoApp-g0zIqH6I/lib/python3.8/site-packages/django/db/models/query.py", line 429, in get
    raise self.model.DoesNotExist(
Auth.models.UserTransport.DoesNotExist: UserTransport matching query does not exist.
[2021-02-02 18:34:23 +0000] [28726] [INFO] Worker exiting (pid: 28726)
[2021-02-02 18:34:23 +0000] [28716] [INFO] Handling signal: term
[2021-02-02 18:34:23 +0000] [28716] [INFO] Shutting down: Master
[2021-02-02 18:34:24 +0000] [29473] [INFO] Starting gunicorn 20.0.4
[2021-02-02 18:34:24 +0000] [29473] [INFO] Listening at: http://127.0.0.1:33333 (29473)
[2021-02-02 18:34:24 +0000] [29473] [INFO] Using worker: sync
[2021-02-02 18:34:24 +0000] [29480] [INFO] Booting worker with pid: 29480
Internal Server Error: /transport/3/
Traceback (most recent call last):
  File "/home/telegrambot/.local/share/virtualenvs/AutoApp-g0zIqH6I/lib/python3.8/site-packages/django/core/handlers/exception.py", line 47, in inner
    response = get_response(request)
  File "/home/telegrambot/.local/share/virtualenvs/AutoApp-g0zIqH6I/lib/python3.8/site-packages/django/core/handlers/base.py", line 179, in _get_response
    response = wrapped_callback(request, *callback_args, **callback_kwargs)
  File "/home/telegrambot/.local/share/virtualenvs/AutoApp-g0zIqH6I/lib/python3.8/site-packages/django/views/decorators/csrf.py", line 54, in wrapped_view
    return view_func(*args, **kwargs)
  File "/home/telegrambot/.local/share/virtualenvs/AutoApp-g0zIqH6I/lib/python3.8/site-packages/django/views/generic/base.py", line 70, in view
    return self.dispatch(request, *args, **kwargs)
  File "/home/telegrambot/.local/share/virtualenvs/AutoApp-g0zIqH6I/lib/python3.8/site-packages/rest_framework/views.py", line 509, in dispatch
    response = self.handle_exception(exc)
  File "/home/telegrambot/.local/share/virtualenvs/AutoApp-g0zIqH6I/lib/python3.8/site-packages/rest_framework/views.py", line 469, in handle_exception
    self.raise_uncaught_exception(exc)
  File "/home/telegrambot/.local/share/virtualenvs/AutoApp-g0zIqH6I/lib/python3.8/site-packages/rest_framework/views.py", line 480, in raise_uncaught_exception
    raise exc
  File "/home/telegrambot/.local/share/virtualenvs/AutoApp-g0zIqH6I/lib/python3.8/site-packages/rest_framework/views.py", line 506, in dispatch
    response = handler(request, *args, **kwargs)
  File "/home/telegrambot/AutoApp/Auth/views.py", line 203, in get
    user = UserTransport.objects.get(emailOrPhone=kwargs['pk'])
  File "/home/telegrambot/.local/share/virtualenvs/AutoApp-g0zIqH6I/lib/python3.8/site-packages/django/db/models/manager.py", line 85, in manager_method
    return getattr(self.get_queryset(), name)(*args, **kwargs)
  File "/home/telegrambot/.local/share/virtualenvs/AutoApp-g0zIqH6I/lib/python3.8/site-packages/django/db/models/query.py", line 429, in get
    raise self.model.DoesNotExist(
Auth.models.UserTransport.DoesNotExist: UserTransport matching query does not exist.
Method Not Allowed: /transport/3/
Internal Server Error: /units/null/
Traceback (most recent call last):
  File "/home/telegrambot/.local/share/virtualenvs/AutoApp-g0zIqH6I/lib/python3.8/site-packages/django/core/handlers/exception.py", line 47, in inner
    response = get_response(request)
  File "/home/telegrambot/.local/share/virtualenvs/AutoApp-g0zIqH6I/lib/python3.8/site-packages/django/core/handlers/base.py", line 179, in _get_response
    response = wrapped_callback(request, *callback_args, **callback_kwargs)
  File "/home/telegrambot/.local/share/virtualenvs/AutoApp-g0zIqH6I/lib/python3.8/site-packages/django/views/decorators/csrf.py", line 54, in wrapped_view
    return view_func(*args, **kwargs)
  File "/home/telegrambot/.local/share/virtualenvs/AutoApp-g0zIqH6I/lib/python3.8/site-packages/django/views/generic/base.py", line 70, in view
    return self.dispatch(request, *args, **kwargs)
  File "/home/telegrambot/.local/share/virtualenvs/AutoApp-g0zIqH6I/lib/python3.8/site-packages/rest_framework/views.py", line 509, in dispatch
    response = self.handle_exception(exc)
  File "/home/telegrambot/.local/share/virtualenvs/AutoApp-g0zIqH6I/lib/python3.8/site-packages/rest_framework/views.py", line 469, in handle_exception
    self.raise_uncaught_exception(exc)
  File "/home/telegrambot/.local/share/virtualenvs/AutoApp-g0zIqH6I/lib/python3.8/site-packages/rest_framework/views.py", line 480, in raise_uncaught_exception
    raise exc
  File "/home/telegrambot/.local/share/virtualenvs/AutoApp-g0zIqH6I/lib/python3.8/site-packages/rest_framework/views.py", line 506, in dispatch
    response = handler(request, *args, **kwargs)
  File "/home/telegrambot/AutoApp/Auth/views.py", line 153, in put
    user = UserTransport.objects.get(emailOrPhone=pk)
  File "/home/telegrambot/.local/share/virtualenvs/AutoApp-g0zIqH6I/lib/python3.8/site-packages/django/db/models/manager.py", line 85, in manager_method
    return getattr(self.get_queryset(), name)(*args, **kwargs)
  File "/home/telegrambot/.local/share/virtualenvs/AutoApp-g0zIqH6I/lib/python3.8/site-packages/django/db/models/query.py", line 429, in get
    raise self.model.DoesNotExist(
Auth.models.UserTransport.DoesNotExist: UserTransport matching query does not exist.
[2021-02-03 04:00:01 +0000] [29473] [INFO] Handling signal: term
[2021-02-03 04:00:01 +0000] [29480] [INFO] Worker exiting (pid: 29480)
[2021-02-03 04:00:02 +0000] [29473] [INFO] Shutting down: Master
[2021-02-03 04:00:24 +0000] [17842] [INFO] Starting gunicorn 20.0.4
[2021-02-03 04:00:24 +0000] [17842] [INFO] Listening at: http://127.0.0.1:33333 (17842)
[2021-02-03 04:00:24 +0000] [17842] [INFO] Using worker: sync
[2021-02-03 04:00:24 +0000] [17979] [INFO] Booting worker with pid: 17979
Not Found: /favicon.ico
Not Found: /favicon.ico
Internal Server Error: /transport/9/
Traceback (most recent call last):
  File "/home/telegrambot/.local/share/virtualenvs/AutoApp-g0zIqH6I/lib/python3.8/site-packages/django/core/handlers/exception.py", line 47, in inner
    response = get_response(request)
  File "/home/telegrambot/.local/share/virtualenvs/AutoApp-g0zIqH6I/lib/python3.8/site-packages/django/core/handlers/base.py", line 179, in _get_response
    response = wrapped_callback(request, *callback_args, **callback_kwargs)
  File "/home/telegrambot/.local/share/virtualenvs/AutoApp-g0zIqH6I/lib/python3.8/site-packages/django/views/decorators/csrf.py", line 54, in wrapped_view
    return view_func(*args, **kwargs)
  File "/home/telegrambot/.local/share/virtualenvs/AutoApp-g0zIqH6I/lib/python3.8/site-packages/django/views/generic/base.py", line 70, in view
    return self.dispatch(request, *args, **kwargs)
  File "/home/telegrambot/.local/share/virtualenvs/AutoApp-g0zIqH6I/lib/python3.8/site-packages/rest_framework/views.py", line 509, in dispatch
    response = self.handle_exception(exc)
  File "/home/telegrambot/.local/share/virtualenvs/AutoApp-g0zIqH6I/lib/python3.8/site-packages/rest_framework/views.py", line 469, in handle_exception
    self.raise_uncaught_exception(exc)
  File "/home/telegrambot/.local/share/virtualenvs/AutoApp-g0zIqH6I/lib/python3.8/site-packages/rest_framework/views.py", line 480, in raise_uncaught_exception
    raise exc
  File "/home/telegrambot/.local/share/virtualenvs/AutoApp-g0zIqH6I/lib/python3.8/site-packages/rest_framework/views.py", line 506, in dispatch
    response = handler(request, *args, **kwargs)
  File "/home/telegrambot/AutoApp/Auth/views.py", line 203, in get
    user = UserTransport.objects.get(emailOrPhone=kwargs['pk'])
  File "/home/telegrambot/.local/share/virtualenvs/AutoApp-g0zIqH6I/lib/python3.8/site-packages/django/db/models/manager.py", line 85, in manager_method
    return getattr(self.get_queryset(), name)(*args, **kwargs)
  File "/home/telegrambot/.local/share/virtualenvs/AutoApp-g0zIqH6I/lib/python3.8/site-packages/django/db/models/query.py", line 429, in get
    raise self.model.DoesNotExist(
Auth.models.UserTransport.DoesNotExist: UserTransport matching query does not exist.
Internal Server Error: /cards/1/
Traceback (most recent call last):
  File "/home/telegrambot/.local/share/virtualenvs/AutoApp-g0zIqH6I/lib/python3.8/site-packages/django/core/handlers/exception.py", line 47, in inner
    response = get_response(request)
  File "/home/telegrambot/.local/share/virtualenvs/AutoApp-g0zIqH6I/lib/python3.8/site-packages/django/core/handlers/base.py", line 179, in _get_response
    response = wrapped_callback(request, *callback_args, **callback_kwargs)
  File "/home/telegrambot/.local/share/virtualenvs/AutoApp-g0zIqH6I/lib/python3.8/site-packages/django/views/decorators/csrf.py", line 54, in wrapped_view
    return view_func(*args, **kwargs)
  File "/home/telegrambot/.local/share/virtualenvs/AutoApp-g0zIqH6I/lib/python3.8/site-packages/django/views/generic/base.py", line 70, in view
    return self.dispatch(request, *args, **kwargs)
  File "/home/telegrambot/.local/share/virtualenvs/AutoApp-g0zIqH6I/lib/python3.8/site-packages/rest_framework/views.py", line 509, in dispatch
    response = self.handle_exception(exc)
  File "/home/telegrambot/.local/share/virtualenvs/AutoApp-g0zIqH6I/lib/python3.8/site-packages/rest_framework/views.py", line 469, in handle_exception
    self.raise_uncaught_exception(exc)
  File "/home/telegrambot/.local/share/virtualenvs/AutoApp-g0zIqH6I/lib/python3.8/site-packages/rest_framework/views.py", line 480, in raise_uncaught_exception
    raise exc
  File "/home/telegrambot/.local/share/virtualenvs/AutoApp-g0zIqH6I/lib/python3.8/site-packages/rest_framework/views.py", line 506, in dispatch
    response = handler(request, *args, **kwargs)
  File "/home/telegrambot/AutoApp/Auth/views.py", line 293, in get
    data = Cards.objects.get(id = kwargs['pk'])
  File "/home/telegrambot/.local/share/virtualenvs/AutoApp-g0zIqH6I/lib/python3.8/site-packages/django/db/models/manager.py", line 85, in manager_method
    return getattr(self.get_queryset(), name)(*args, **kwargs)
  File "/home/telegrambot/.local/share/virtualenvs/AutoApp-g0zIqH6I/lib/python3.8/site-packages/django/db/models/query.py", line 429, in get
    raise self.model.DoesNotExist(
Auth.models.Cards.DoesNotExist: Cards matching query does not exist.
Internal Server Error: /cards/2/
Traceback (most recent call last):
  File "/home/telegrambot/.local/share/virtualenvs/AutoApp-g0zIqH6I/lib/python3.8/site-packages/django/core/handlers/exception.py", line 47, in inner
    response = get_response(request)
  File "/home/telegrambot/.local/share/virtualenvs/AutoApp-g0zIqH6I/lib/python3.8/site-packages/django/core/handlers/base.py", line 179, in _get_response
    response = wrapped_callback(request, *callback_args, **callback_kwargs)
  File "/home/telegrambot/.local/share/virtualenvs/AutoApp-g0zIqH6I/lib/python3.8/site-packages/django/views/decorators/csrf.py", line 54, in wrapped_view
    return view_func(*args, **kwargs)
  File "/home/telegrambot/.local/share/virtualenvs/AutoApp-g0zIqH6I/lib/python3.8/site-packages/django/views/generic/base.py", line 70, in view
    return self.dispatch(request, *args, **kwargs)
  File "/home/telegrambot/.local/share/virtualenvs/AutoApp-g0zIqH6I/lib/python3.8/site-packages/rest_framework/views.py", line 509, in dispatch
    response = self.handle_exception(exc)
  File "/home/telegrambot/.local/share/virtualenvs/AutoApp-g0zIqH6I/lib/python3.8/site-packages/rest_framework/views.py", line 469, in handle_exception
    self.raise_uncaught_exception(exc)
  File "/home/telegrambot/.local/share/virtualenvs/AutoApp-g0zIqH6I/lib/python3.8/site-packages/rest_framework/views.py", line 480, in raise_uncaught_exception
    raise exc
  File "/home/telegrambot/.local/share/virtualenvs/AutoApp-g0zIqH6I/lib/python3.8/site-packages/rest_framework/views.py", line 506, in dispatch
    response = handler(request, *args, **kwargs)
  File "/home/telegrambot/AutoApp/Auth/views.py", line 293, in get
    data = Cards.objects.get(id = kwargs['pk'])
  File "/home/telegrambot/.local/share/virtualenvs/AutoApp-g0zIqH6I/lib/python3.8/site-packages/django/db/models/manager.py", line 85, in manager_method
    return getattr(self.get_queryset(), name)(*args, **kwargs)
  File "/home/telegrambot/.local/share/virtualenvs/AutoApp-g0zIqH6I/lib/python3.8/site-packages/django/db/models/query.py", line 429, in get
    raise self.model.DoesNotExist(
Auth.models.Cards.DoesNotExist: Cards matching query does not exist.
Internal Server Error: /cards/1/
Traceback (most recent call last):
  File "/home/telegrambot/.local/share/virtualenvs/AutoApp-g0zIqH6I/lib/python3.8/site-packages/django/core/handlers/exception.py", line 47, in inner
    response = get_response(request)
  File "/home/telegrambot/.local/share/virtualenvs/AutoApp-g0zIqH6I/lib/python3.8/site-packages/django/core/handlers/base.py", line 179, in _get_response
    response = wrapped_callback(request, *callback_args, **callback_kwargs)
  File "/home/telegrambot/.local/share/virtualenvs/AutoApp-g0zIqH6I/lib/python3.8/site-packages/django/views/decorators/csrf.py", line 54, in wrapped_view
    return view_func(*args, **kwargs)
  File "/home/telegrambot/.local/share/virtualenvs/AutoApp-g0zIqH6I/lib/python3.8/site-packages/django/views/generic/base.py", line 70, in view
    return self.dispatch(request, *args, **kwargs)
  File "/home/telegrambot/.local/share/virtualenvs/AutoApp-g0zIqH6I/lib/python3.8/site-packages/rest_framework/views.py", line 509, in dispatch
    response = self.handle_exception(exc)
  File "/home/telegrambot/.local/share/virtualenvs/AutoApp-g0zIqH6I/lib/python3.8/site-packages/rest_framework/views.py", line 469, in handle_exception
    self.raise_uncaught_exception(exc)
  File "/home/telegrambot/.local/share/virtualenvs/AutoApp-g0zIqH6I/lib/python3.8/site-packages/rest_framework/views.py", line 480, in raise_uncaught_exception
    raise exc
  File "/home/telegrambot/.local/share/virtualenvs/AutoApp-g0zIqH6I/lib/python3.8/site-packages/rest_framework/views.py", line 506, in dispatch
    response = handler(request, *args, **kwargs)
  File "/home/telegrambot/AutoApp/Auth/views.py", line 293, in get
    data = Cards.objects.get(id = kwargs['pk'])
  File "/home/telegrambot/.local/share/virtualenvs/AutoApp-g0zIqH6I/lib/python3.8/site-packages/django/db/models/manager.py", line 85, in manager_method
    return getattr(self.get_queryset(), name)(*args, **kwargs)
  File "/home/telegrambot/.local/share/virtualenvs/AutoApp-g0zIqH6I/lib/python3.8/site-packages/django/db/models/query.py", line 429, in get
    raise self.model.DoesNotExist(
Auth.models.Cards.DoesNotExist: Cards matching query does not exist.
Internal Server Error: /cards/3/
Traceback (most recent call last):
  File "/home/telegrambot/.local/share/virtualenvs/AutoApp-g0zIqH6I/lib/python3.8/site-packages/django/core/handlers/exception.py", line 47, in inner
    response = get_response(request)
  File "/home/telegrambot/.local/share/virtualenvs/AutoApp-g0zIqH6I/lib/python3.8/site-packages/django/core/handlers/base.py", line 179, in _get_response
    response = wrapped_callback(request, *callback_args, **callback_kwargs)
  File "/home/telegrambot/.local/share/virtualenvs/AutoApp-g0zIqH6I/lib/python3.8/site-packages/django/views/decorators/csrf.py", line 54, in wrapped_view
    return view_func(*args, **kwargs)
  File "/home/telegrambot/.local/share/virtualenvs/AutoApp-g0zIqH6I/lib/python3.8/site-packages/django/views/generic/base.py", line 70, in view
    return self.dispatch(request, *args, **kwargs)
  File "/home/telegrambot/.local/share/virtualenvs/AutoApp-g0zIqH6I/lib/python3.8/site-packages/rest_framework/views.py", line 509, in dispatch
    response = self.handle_exception(exc)
  File "/home/telegrambot/.local/share/virtualenvs/AutoApp-g0zIqH6I/lib/python3.8/site-packages/rest_framework/views.py", line 469, in handle_exception
    self.raise_uncaught_exception(exc)
  File "/home/telegrambot/.local/share/virtualenvs/AutoApp-g0zIqH6I/lib/python3.8/site-packages/rest_framework/views.py", line 480, in raise_uncaught_exception
    raise exc
  File "/home/telegrambot/.local/share/virtualenvs/AutoApp-g0zIqH6I/lib/python3.8/site-packages/rest_framework/views.py", line 506, in dispatch
    response = handler(request, *args, **kwargs)
  File "/home/telegrambot/AutoApp/Auth/views.py", line 293, in get
    data = Cards.objects.get(id = kwargs['pk'])
  File "/home/telegrambot/.local/share/virtualenvs/AutoApp-g0zIqH6I/lib/python3.8/site-packages/django/db/models/manager.py", line 85, in manager_method
    return getattr(self.get_queryset(), name)(*args, **kwargs)
  File "/home/telegrambot/.local/share/virtualenvs/AutoApp-g0zIqH6I/lib/python3.8/site-packages/django/db/models/query.py", line 429, in get
    raise self.model.DoesNotExist(
Auth.models.Cards.DoesNotExist: Cards matching query does not exist.
Internal Server Error: /cards/5/
Traceback (most recent call last):
  File "/home/telegrambot/.local/share/virtualenvs/AutoApp-g0zIqH6I/lib/python3.8/site-packages/django/core/handlers/exception.py", line 47, in inner
    response = get_response(request)
  File "/home/telegrambot/.local/share/virtualenvs/AutoApp-g0zIqH6I/lib/python3.8/site-packages/django/core/handlers/base.py", line 179, in _get_response
    response = wrapped_callback(request, *callback_args, **callback_kwargs)
  File "/home/telegrambot/.local/share/virtualenvs/AutoApp-g0zIqH6I/lib/python3.8/site-packages/django/views/decorators/csrf.py", line 54, in wrapped_view
    return view_func(*args, **kwargs)
  File "/home/telegrambot/.local/share/virtualenvs/AutoApp-g0zIqH6I/lib/python3.8/site-packages/django/views/generic/base.py", line 70, in view
    return self.dispatch(request, *args, **kwargs)
  File "/home/telegrambot/.local/share/virtualenvs/AutoApp-g0zIqH6I/lib/python3.8/site-packages/rest_framework/views.py", line 509, in dispatch
    response = self.handle_exception(exc)
  File "/home/telegrambot/.local/share/virtualenvs/AutoApp-g0zIqH6I/lib/python3.8/site-packages/rest_framework/views.py", line 469, in handle_exception
    self.raise_uncaught_exception(exc)
  File "/home/telegrambot/.local/share/virtualenvs/AutoApp-g0zIqH6I/lib/python3.8/site-packages/rest_framework/views.py", line 480, in raise_uncaught_exception
    raise exc
  File "/home/telegrambot/.local/share/virtualenvs/AutoApp-g0zIqH6I/lib/python3.8/site-packages/rest_framework/views.py", line 506, in dispatch
    response = handler(request, *args, **kwargs)
  File "/home/telegrambot/AutoApp/Auth/views.py", line 293, in get
    data = Cards.objects.get(id = kwargs['pk'])
  File "/home/telegrambot/.local/share/virtualenvs/AutoApp-g0zIqH6I/lib/python3.8/site-packages/django/db/models/manager.py", line 85, in manager_method
    return getattr(self.get_queryset(), name)(*args, **kwargs)
  File "/home/telegrambot/.local/share/virtualenvs/AutoApp-g0zIqH6I/lib/python3.8/site-packages/django/db/models/query.py", line 429, in get
    raise self.model.DoesNotExist(
Auth.models.Cards.DoesNotExist: Cards matching query does not exist.
Internal Server Error: /cards/5/
Traceback (most recent call last):
  File "/home/telegrambot/.local/share/virtualenvs/AutoApp-g0zIqH6I/lib/python3.8/site-packages/django/core/handlers/exception.py", line 47, in inner
    response = get_response(request)
  File "/home/telegrambot/.local/share/virtualenvs/AutoApp-g0zIqH6I/lib/python3.8/site-packages/django/core/handlers/base.py", line 179, in _get_response
    response = wrapped_callback(request, *callback_args, **callback_kwargs)
  File "/home/telegrambot/.local/share/virtualenvs/AutoApp-g0zIqH6I/lib/python3.8/site-packages/django/views/decorators/csrf.py", line 54, in wrapped_view
    return view_func(*args, **kwargs)
  File "/home/telegrambot/.local/share/virtualenvs/AutoApp-g0zIqH6I/lib/python3.8/site-packages/django/views/generic/base.py", line 70, in view
    return self.dispatch(request, *args, **kwargs)
  File "/home/telegrambot/.local/share/virtualenvs/AutoApp-g0zIqH6I/lib/python3.8/site-packages/rest_framework/views.py", line 509, in dispatch
    response = self.handle_exception(exc)
  File "/home/telegrambot/.local/share/virtualenvs/AutoApp-g0zIqH6I/lib/python3.8/site-packages/rest_framework/views.py", line 469, in handle_exception
    self.raise_uncaught_exception(exc)
  File "/home/telegrambot/.local/share/virtualenvs/AutoApp-g0zIqH6I/lib/python3.8/site-packages/rest_framework/views.py", line 480, in raise_uncaught_exception
    raise exc
  File "/home/telegrambot/.local/share/virtualenvs/AutoApp-g0zIqH6I/lib/python3.8/site-packages/rest_framework/views.py", line 506, in dispatch
    response = handler(request, *args, **kwargs)
  File "/home/telegrambot/AutoApp/Auth/views.py", line 293, in get
  File "/home/telegrambot/.local/share/virtualenvs/AutoApp-g0zIqH6I/lib/python3.8/site-packages/django/db/models/manager.py", line 85, in manager_method
    return getattr(self.get_queryset(), name)(*args, **kwargs)
  File "/home/telegrambot/.local/share/virtualenvs/AutoApp-g0zIqH6I/lib/python3.8/site-packages/django/db/models/query.py", line 429, in get
    raise self.model.DoesNotExist(
Auth.models.Cards.DoesNotExist: Cards matching query does not exist.
Internal Server Error: /cards/5/
Traceback (most recent call last):
  File "/home/telegrambot/.local/share/virtualenvs/AutoApp-g0zIqH6I/lib/python3.8/site-packages/django/core/handlers/exception.py", line 47, in inner
    response = get_response(request)
  File "/home/telegrambot/.local/share/virtualenvs/AutoApp-g0zIqH6I/lib/python3.8/site-packages/django/core/handlers/base.py", line 179, in _get_response
    response = wrapped_callback(request, *callback_args, **callback_kwargs)
  File "/home/telegrambot/.local/share/virtualenvs/AutoApp-g0zIqH6I/lib/python3.8/site-packages/django/views/decorators/csrf.py", line 54, in wrapped_view
    return view_func(*args, **kwargs)
  File "/home/telegrambot/.local/share/virtualenvs/AutoApp-g0zIqH6I/lib/python3.8/site-packages/django/views/generic/base.py", line 70, in view
    return self.dispatch(request, *args, **kwargs)
  File "/home/telegrambot/.local/share/virtualenvs/AutoApp-g0zIqH6I/lib/python3.8/site-packages/rest_framework/views.py", line 509, in dispatch
    response = self.handle_exception(exc)
  File "/home/telegrambot/.local/share/virtualenvs/AutoApp-g0zIqH6I/lib/python3.8/site-packages/rest_framework/views.py", line 469, in handle_exception
    self.raise_uncaught_exception(exc)
  File "/home/telegrambot/.local/share/virtualenvs/AutoApp-g0zIqH6I/lib/python3.8/site-packages/rest_framework/views.py", line 480, in raise_uncaught_exception
    raise exc
  File "/home/telegrambot/.local/share/virtualenvs/AutoApp-g0zIqH6I/lib/python3.8/site-packages/rest_framework/views.py", line 506, in dispatch
    response = handler(request, *args, **kwargs)
  File "/home/telegrambot/AutoApp/Auth/views.py", line 293, in get
  File "/home/telegrambot/.local/share/virtualenvs/AutoApp-g0zIqH6I/lib/python3.8/site-packages/django/db/models/manager.py", line 85, in manager_method
    return getattr(self.get_queryset(), name)(*args, **kwargs)
  File "/home/telegrambot/.local/share/virtualenvs/AutoApp-g0zIqH6I/lib/python3.8/site-packages/django/db/models/query.py", line 429, in get
    raise self.model.DoesNotExist(
Auth.models.Cards.DoesNotExist: Cards matching query does not exist.
Internal Server Error: /cards/5/
Traceback (most recent call last):
  File "/home/telegrambot/.local/share/virtualenvs/AutoApp-g0zIqH6I/lib/python3.8/site-packages/django/core/handlers/exception.py", line 47, in inner
    response = get_response(request)
  File "/home/telegrambot/.local/share/virtualenvs/AutoApp-g0zIqH6I/lib/python3.8/site-packages/django/core/handlers/base.py", line 179, in _get_response
    response = wrapped_callback(request, *callback_args, **callback_kwargs)
  File "/home/telegrambot/.local/share/virtualenvs/AutoApp-g0zIqH6I/lib/python3.8/site-packages/django/views/decorators/csrf.py", line 54, in wrapped_view
    return view_func(*args, **kwargs)
  File "/home/telegrambot/.local/share/virtualenvs/AutoApp-g0zIqH6I/lib/python3.8/site-packages/django/views/generic/base.py", line 70, in view
    return self.dispatch(request, *args, **kwargs)
  File "/home/telegrambot/.local/share/virtualenvs/AutoApp-g0zIqH6I/lib/python3.8/site-packages/rest_framework/views.py", line 509, in dispatch
    response = self.handle_exception(exc)
  File "/home/telegrambot/.local/share/virtualenvs/AutoApp-g0zIqH6I/lib/python3.8/site-packages/rest_framework/views.py", line 469, in handle_exception
    self.raise_uncaught_exception(exc)
  File "/home/telegrambot/.local/share/virtualenvs/AutoApp-g0zIqH6I/lib/python3.8/site-packages/rest_framework/views.py", line 480, in raise_uncaught_exception
    raise exc
  File "/home/telegrambot/.local/share/virtualenvs/AutoApp-g0zIqH6I/lib/python3.8/site-packages/rest_framework/views.py", line 506, in dispatch
    response = handler(request, *args, **kwargs)
  File "/home/telegrambot/AutoApp/Auth/views.py", line 293, in get
  File "/home/telegrambot/.local/share/virtualenvs/AutoApp-g0zIqH6I/lib/python3.8/site-packages/django/db/models/manager.py", line 85, in manager_method
    return getattr(self.get_queryset(), name)(*args, **kwargs)
  File "/home/telegrambot/.local/share/virtualenvs/AutoApp-g0zIqH6I/lib/python3.8/site-packages/django/db/models/query.py", line 429, in get
    raise self.model.DoesNotExist(
Auth.models.Cards.DoesNotExist: Cards matching query does not exist.
[2021-02-03 13:40:15 +0000] [17979] [INFO] Worker exiting (pid: 17979)
[2021-02-03 13:40:15 +0000] [17842] [INFO] Handling signal: term
[2021-02-03 13:40:15 +0000] [17842] [INFO] Shutting down: Master
[2021-02-03 13:40:16 +0000] [6416] [INFO] Starting gunicorn 20.0.4
[2021-02-03 13:40:16 +0000] [6416] [INFO] Listening at: http://127.0.0.1:33333 (6416)
[2021-02-03 13:40:16 +0000] [6416] [INFO] Using worker: sync
[2021-02-03 13:40:16 +0000] [6423] [INFO] Booting worker with pid: 6423
Not Found: /favicon.ico
[2021-02-04 04:00:01 +0000] [6423] [INFO] Worker exiting (pid: 6423)
[2021-02-04 04:00:01 +0000] [6416] [INFO] Handling signal: term
[2021-02-04 04:00:02 +0000] [6416] [INFO] Shutting down: Master
[2021-02-04 04:00:24 +0000] [3920] [INFO] Starting gunicorn 20.0.4
[2021-02-04 04:00:24 +0000] [3920] [INFO] Listening at: http://127.0.0.1:33333 (3920)
[2021-02-04 04:00:24 +0000] [3920] [INFO] Using worker: sync
[2021-02-04 04:00:24 +0000] [4048] [INFO] Booting worker with pid: 4048
Not Found: /
Not Found: /favicon.ico
Internal Server Error: /cards/2}/
Traceback (most recent call last):
  File "/home/telegrambot/.local/share/virtualenvs/AutoApp-g0zIqH6I/lib/python3.8/site-packages/django/db/models/fields/__init__.py", line 1774, in get_prep_value
    return int(value)
ValueError: invalid literal for int() with base 10: '2}'

The above exception was the direct cause of the following exception:

Traceback (most recent call last):
  File "/home/telegrambot/.local/share/virtualenvs/AutoApp-g0zIqH6I/lib/python3.8/site-packages/django/core/handlers/exception.py", line 47, in inner
    response = get_response(request)
  File "/home/telegrambot/.local/share/virtualenvs/AutoApp-g0zIqH6I/lib/python3.8/site-packages/django/core/handlers/base.py", line 179, in _get_response
    response = wrapped_callback(request, *callback_args, **callback_kwargs)
  File "/home/telegrambot/.local/share/virtualenvs/AutoApp-g0zIqH6I/lib/python3.8/site-packages/django/views/decorators/csrf.py", line 54, in wrapped_view
    return view_func(*args, **kwargs)
  File "/home/telegrambot/.local/share/virtualenvs/AutoApp-g0zIqH6I/lib/python3.8/site-packages/django/views/generic/base.py", line 70, in view
    return self.dispatch(request, *args, **kwargs)
  File "/home/telegrambot/.local/share/virtualenvs/AutoApp-g0zIqH6I/lib/python3.8/site-packages/rest_framework/views.py", line 509, in dispatch
    response = self.handle_exception(exc)
  File "/home/telegrambot/.local/share/virtualenvs/AutoApp-g0zIqH6I/lib/python3.8/site-packages/rest_framework/views.py", line 469, in handle_exception
    self.raise_uncaught_exception(exc)
  File "/home/telegrambot/.local/share/virtualenvs/AutoApp-g0zIqH6I/lib/python3.8/site-packages/rest_framework/views.py", line 480, in raise_uncaught_exception
    raise exc
  File "/home/telegrambot/.local/share/virtualenvs/AutoApp-g0zIqH6I/lib/python3.8/site-packages/rest_framework/views.py", line 506, in dispatch
    response = handler(request, *args, **kwargs)
  File "/home/telegrambot/AutoApp/Auth/views.py", line 375, in delete
    card = Card.objects.filter(pk = pk)
  File "/home/telegrambot/.local/share/virtualenvs/AutoApp-g0zIqH6I/lib/python3.8/site-packages/django/db/models/manager.py", line 85, in manager_method
    return getattr(self.get_queryset(), name)(*args, **kwargs)
  File "/home/telegrambot/.local/share/virtualenvs/AutoApp-g0zIqH6I/lib/python3.8/site-packages/django/db/models/query.py", line 942, in filter
    return self._filter_or_exclude(False, *args, **kwargs)
  File "/home/telegrambot/.local/share/virtualenvs/AutoApp-g0zIqH6I/lib/python3.8/site-packages/django/db/models/query.py", line 962, in _filter_or_exclude
    clone._filter_or_exclude_inplace(negate, *args, **kwargs)
  File "/home/telegrambot/.local/share/virtualenvs/AutoApp-g0zIqH6I/lib/python3.8/site-packages/django/db/models/query.py", line 969, in _filter_or_exclude_inplace
    self._query.add_q(Q(*args, **kwargs))
  File "/home/telegrambot/.local/share/virtualenvs/AutoApp-g0zIqH6I/lib/python3.8/site-packages/django/db/models/sql/query.py", line 1358, in add_q
    clause, _ = self._add_q(q_object, self.used_aliases)
  File "/home/telegrambot/.local/share/virtualenvs/AutoApp-g0zIqH6I/lib/python3.8/site-packages/django/db/models/sql/query.py", line 1377, in _add_q
    child_clause, needed_inner = self.build_filter(
  File "/home/telegrambot/.local/share/virtualenvs/AutoApp-g0zIqH6I/lib/python3.8/site-packages/django/db/models/sql/query.py", line 1319, in build_filter
    condition = self.build_lookup(lookups, col, value)
  File "/home/telegrambot/.local/share/virtualenvs/AutoApp-g0zIqH6I/lib/python3.8/site-packages/django/db/models/sql/query.py", line 1165, in build_lookup
    lookup = lookup_class(lhs, rhs)
  File "/home/telegrambot/.local/share/virtualenvs/AutoApp-g0zIqH6I/lib/python3.8/site-packages/django/db/models/lookups.py", line 24, in __init__
    self.rhs = self.get_prep_lookup()
  File "/home/telegrambot/.local/share/virtualenvs/AutoApp-g0zIqH6I/lib/python3.8/site-packages/django/db/models/lookups.py", line 76, in get_prep_lookup
    return self.lhs.output_field.get_prep_value(self.rhs)
  File "/home/telegrambot/.local/share/virtualenvs/AutoApp-g0zIqH6I/lib/python3.8/site-packages/django/db/models/fields/__init__.py", line 1776, in get_prep_value
    raise e.__class__(
ValueError: Field 'id' expected a number but got '2}'.
Not Found: /trasnport/
Internal Server Error: /cards/2}/
Traceback (most recent call last):
  File "/home/telegrambot/.local/share/virtualenvs/AutoApp-g0zIqH6I/lib/python3.8/site-packages/django/db/models/fields/__init__.py", line 1774, in get_prep_value
    return int(value)
ValueError: invalid literal for int() with base 10: '2}'

The above exception was the direct cause of the following exception:

Traceback (most recent call last):
  File "/home/telegrambot/.local/share/virtualenvs/AutoApp-g0zIqH6I/lib/python3.8/site-packages/django/core/handlers/exception.py", line 47, in inner
    response = get_response(request)
  File "/home/telegrambot/.local/share/virtualenvs/AutoApp-g0zIqH6I/lib/python3.8/site-packages/django/core/handlers/base.py", line 179, in _get_response
    response = wrapped_callback(request, *callback_args, **callback_kwargs)
  File "/home/telegrambot/.local/share/virtualenvs/AutoApp-g0zIqH6I/lib/python3.8/site-packages/django/views/decorators/csrf.py", line 54, in wrapped_view
    return view_func(*args, **kwargs)
  File "/home/telegrambot/.local/share/virtualenvs/AutoApp-g0zIqH6I/lib/python3.8/site-packages/django/views/generic/base.py", line 70, in view
    return self.dispatch(request, *args, **kwargs)
  File "/home/telegrambot/.local/share/virtualenvs/AutoApp-g0zIqH6I/lib/python3.8/site-packages/rest_framework/views.py", line 509, in dispatch
    response = self.handle_exception(exc)
  File "/home/telegrambot/.local/share/virtualenvs/AutoApp-g0zIqH6I/lib/python3.8/site-packages/rest_framework/views.py", line 469, in handle_exception
    self.raise_uncaught_exception(exc)
  File "/home/telegrambot/.local/share/virtualenvs/AutoApp-g0zIqH6I/lib/python3.8/site-packages/rest_framework/views.py", line 480, in raise_uncaught_exception
    raise exc
  File "/home/telegrambot/.local/share/virtualenvs/AutoApp-g0zIqH6I/lib/python3.8/site-packages/rest_framework/views.py", line 506, in dispatch
    response = handler(request, *args, **kwargs)
  File "/home/telegrambot/AutoApp/Auth/views.py", line 375, in delete
    card = Card.objects.filter(pk = pk)
  File "/home/telegrambot/.local/share/virtualenvs/AutoApp-g0zIqH6I/lib/python3.8/site-packages/django/db/models/manager.py", line 85, in manager_method
    return getattr(self.get_queryset(), name)(*args, **kwargs)
  File "/home/telegrambot/.local/share/virtualenvs/AutoApp-g0zIqH6I/lib/python3.8/site-packages/django/db/models/query.py", line 942, in filter
    return self._filter_or_exclude(False, *args, **kwargs)
  File "/home/telegrambot/.local/share/virtualenvs/AutoApp-g0zIqH6I/lib/python3.8/site-packages/django/db/models/query.py", line 962, in _filter_or_exclude
    clone._filter_or_exclude_inplace(negate, *args, **kwargs)
  File "/home/telegrambot/.local/share/virtualenvs/AutoApp-g0zIqH6I/lib/python3.8/site-packages/django/db/models/query.py", line 969, in _filter_or_exclude_inplace
    self._query.add_q(Q(*args, **kwargs))
  File "/home/telegrambot/.local/share/virtualenvs/AutoApp-g0zIqH6I/lib/python3.8/site-packages/django/db/models/sql/query.py", line 1358, in add_q
    clause, _ = self._add_q(q_object, self.used_aliases)
  File "/home/telegrambot/.local/share/virtualenvs/AutoApp-g0zIqH6I/lib/python3.8/site-packages/django/db/models/sql/query.py", line 1377, in _add_q
    child_clause, needed_inner = self.build_filter(
  File "/home/telegrambot/.local/share/virtualenvs/AutoApp-g0zIqH6I/lib/python3.8/site-packages/django/db/models/sql/query.py", line 1319, in build_filter
    condition = self.build_lookup(lookups, col, value)
  File "/home/telegrambot/.local/share/virtualenvs/AutoApp-g0zIqH6I/lib/python3.8/site-packages/django/db/models/sql/query.py", line 1165, in build_lookup
    lookup = lookup_class(lhs, rhs)
  File "/home/telegrambot/.local/share/virtualenvs/AutoApp-g0zIqH6I/lib/python3.8/site-packages/django/db/models/lookups.py", line 24, in __init__
    self.rhs = self.get_prep_lookup()
  File "/home/telegrambot/.local/share/virtualenvs/AutoApp-g0zIqH6I/lib/python3.8/site-packages/django/db/models/lookups.py", line 76, in get_prep_lookup
    return self.lhs.output_field.get_prep_value(self.rhs)
  File "/home/telegrambot/.local/share/virtualenvs/AutoApp-g0zIqH6I/lib/python3.8/site-packages/django/db/models/fields/__init__.py", line 1776, in get_prep_value
    raise e.__class__(
ValueError: Field 'id' expected a number but got '2}'.
Not Found: /
Internal Server Error: /recomendations/
Traceback (most recent call last):
  File "/home/telegrambot/.local/share/virtualenvs/AutoApp-g0zIqH6I/lib/python3.8/site-packages/django/core/handlers/exception.py", line 47, in inner
    response = get_response(request)
  File "/home/telegrambot/.local/share/virtualenvs/AutoApp-g0zIqH6I/lib/python3.8/site-packages/django/core/handlers/base.py", line 179, in _get_response
    response = wrapped_callback(request, *callback_args, **callback_kwargs)
  File "/home/telegrambot/.local/share/virtualenvs/AutoApp-g0zIqH6I/lib/python3.8/site-packages/django/views/decorators/csrf.py", line 54, in wrapped_view
    return view_func(*args, **kwargs)
  File "/home/telegrambot/.local/share/virtualenvs/AutoApp-g0zIqH6I/lib/python3.8/site-packages/django/views/generic/base.py", line 70, in view
    return self.dispatch(request, *args, **kwargs)
  File "/home/telegrambot/.local/share/virtualenvs/AutoApp-g0zIqH6I/lib/python3.8/site-packages/rest_framework/views.py", line 509, in dispatch
    response = self.handle_exception(exc)
  File "/home/telegrambot/.local/share/virtualenvs/AutoApp-g0zIqH6I/lib/python3.8/site-packages/rest_framework/views.py", line 469, in handle_exception
    self.raise_uncaught_exception(exc)
  File "/home/telegrambot/.local/share/virtualenvs/AutoApp-g0zIqH6I/lib/python3.8/site-packages/rest_framework/views.py", line 480, in raise_uncaught_exception
    raise exc
  File "/home/telegrambot/.local/share/virtualenvs/AutoApp-g0zIqH6I/lib/python3.8/site-packages/rest_framework/views.py", line 506, in dispatch
    response = handler(request, *args, **kwargs)
  File "/home/telegrambot/AutoApp/Auth/views.py", line 177, in get
    data = ModelRegister.objects.get(id = kwargs['pk'])
KeyError: 'pk'
Not Found: /
Internal Server Error: /recomendations/null/
Traceback (most recent call last):
  File "/home/telegrambot/.local/share/virtualenvs/AutoApp-g0zIqH6I/lib/python3.8/site-packages/django/db/models/fields/__init__.py", line 1774, in get_prep_value
    return int(value)
ValueError: invalid literal for int() with base 10: 'null'

The above exception was the direct cause of the following exception:

Traceback (most recent call last):
  File "/home/telegrambot/.local/share/virtualenvs/AutoApp-g0zIqH6I/lib/python3.8/site-packages/django/core/handlers/exception.py", line 47, in inner
    response = get_response(request)
  File "/home/telegrambot/.local/share/virtualenvs/AutoApp-g0zIqH6I/lib/python3.8/site-packages/django/core/handlers/base.py", line 179, in _get_response
    response = wrapped_callback(request, *callback_args, **callback_kwargs)
  File "/home/telegrambot/.local/share/virtualenvs/AutoApp-g0zIqH6I/lib/python3.8/site-packages/django/views/decorators/csrf.py", line 54, in wrapped_view
    return view_func(*args, **kwargs)
  File "/home/telegrambot/.local/share/virtualenvs/AutoApp-g0zIqH6I/lib/python3.8/site-packages/django/views/generic/base.py", line 70, in view
    return self.dispatch(request, *args, **kwargs)
  File "/home/telegrambot/.local/share/virtualenvs/AutoApp-g0zIqH6I/lib/python3.8/site-packages/rest_framework/views.py", line 509, in dispatch
    response = self.handle_exception(exc)
  File "/home/telegrambot/.local/share/virtualenvs/AutoApp-g0zIqH6I/lib/python3.8/site-packages/rest_framework/views.py", line 469, in handle_exception
    self.raise_uncaught_exception(exc)
  File "/home/telegrambot/.local/share/virtualenvs/AutoApp-g0zIqH6I/lib/python3.8/site-packages/rest_framework/views.py", line 480, in raise_uncaught_exception
    raise exc
  File "/home/telegrambot/.local/share/virtualenvs/AutoApp-g0zIqH6I/lib/python3.8/site-packages/rest_framework/views.py", line 506, in dispatch
    response = handler(request, *args, **kwargs)
  File "/home/telegrambot/AutoApp/Auth/views.py", line 177, in get
    data = ModelRegister.objects.get(id = kwargs['pk'])
  File "/home/telegrambot/.local/share/virtualenvs/AutoApp-g0zIqH6I/lib/python3.8/site-packages/django/db/models/manager.py", line 85, in manager_method
    return getattr(self.get_queryset(), name)(*args, **kwargs)
  File "/home/telegrambot/.local/share/virtualenvs/AutoApp-g0zIqH6I/lib/python3.8/site-packages/django/db/models/query.py", line 418, in get
    clone = self._chain() if self.query.combinator else self.filter(*args, **kwargs)
  File "/home/telegrambot/.local/share/virtualenvs/AutoApp-g0zIqH6I/lib/python3.8/site-packages/django/db/models/query.py", line 942, in filter
    return self._filter_or_exclude(False, *args, **kwargs)
  File "/home/telegrambot/.local/share/virtualenvs/AutoApp-g0zIqH6I/lib/python3.8/site-packages/django/db/models/query.py", line 962, in _filter_or_exclude
    clone._filter_or_exclude_inplace(negate, *args, **kwargs)
  File "/home/telegrambot/.local/share/virtualenvs/AutoApp-g0zIqH6I/lib/python3.8/site-packages/django/db/models/query.py", line 969, in _filter_or_exclude_inplace
    self._query.add_q(Q(*args, **kwargs))
  File "/home/telegrambot/.local/share/virtualenvs/AutoApp-g0zIqH6I/lib/python3.8/site-packages/django/db/models/sql/query.py", line 1358, in add_q
    clause, _ = self._add_q(q_object, self.used_aliases)
  File "/home/telegrambot/.local/share/virtualenvs/AutoApp-g0zIqH6I/lib/python3.8/site-packages/django/db/models/sql/query.py", line 1377, in _add_q
    child_clause, needed_inner = self.build_filter(
  File "/home/telegrambot/.local/share/virtualenvs/AutoApp-g0zIqH6I/lib/python3.8/site-packages/django/db/models/sql/query.py", line 1319, in build_filter
    condition = self.build_lookup(lookups, col, value)
  File "/home/telegrambot/.local/share/virtualenvs/AutoApp-g0zIqH6I/lib/python3.8/site-packages/django/db/models/sql/query.py", line 1165, in build_lookup
    lookup = lookup_class(lhs, rhs)
  File "/home/telegrambot/.local/share/virtualenvs/AutoApp-g0zIqH6I/lib/python3.8/site-packages/django/db/models/lookups.py", line 24, in __init__
    self.rhs = self.get_prep_lookup()
  File "/home/telegrambot/.local/share/virtualenvs/AutoApp-g0zIqH6I/lib/python3.8/site-packages/django/db/models/lookups.py", line 76, in get_prep_lookup
    return self.lhs.output_field.get_prep_value(self.rhs)
  File "/home/telegrambot/.local/share/virtualenvs/AutoApp-g0zIqH6I/lib/python3.8/site-packages/django/db/models/fields/__init__.py", line 1776, in get_prep_value
    raise e.__class__(
ValueError: Field 'id' expected a number but got 'null'.
Internal Server Error: /recomendations/null/
Traceback (most recent call last):
  File "/home/telegrambot/.local/share/virtualenvs/AutoApp-g0zIqH6I/lib/python3.8/site-packages/django/db/models/fields/__init__.py", line 1774, in get_prep_value
    return int(value)
ValueError: invalid literal for int() with base 10: 'null'

The above exception was the direct cause of the following exception:

Traceback (most recent call last):
  File "/home/telegrambot/.local/share/virtualenvs/AutoApp-g0zIqH6I/lib/python3.8/site-packages/django/core/handlers/exception.py", line 47, in inner
    response = get_response(request)
  File "/home/telegrambot/.local/share/virtualenvs/AutoApp-g0zIqH6I/lib/python3.8/site-packages/django/core/handlers/base.py", line 179, in _get_response
    response = wrapped_callback(request, *callback_args, **callback_kwargs)
  File "/home/telegrambot/.local/share/virtualenvs/AutoApp-g0zIqH6I/lib/python3.8/site-packages/django/views/decorators/csrf.py", line 54, in wrapped_view
    return view_func(*args, **kwargs)
  File "/home/telegrambot/.local/share/virtualenvs/AutoApp-g0zIqH6I/lib/python3.8/site-packages/django/views/generic/base.py", line 70, in view
    return self.dispatch(request, *args, **kwargs)
  File "/home/telegrambot/.local/share/virtualenvs/AutoApp-g0zIqH6I/lib/python3.8/site-packages/rest_framework/views.py", line 509, in dispatch
    response = self.handle_exception(exc)
  File "/home/telegrambot/.local/share/virtualenvs/AutoApp-g0zIqH6I/lib/python3.8/site-packages/rest_framework/views.py", line 469, in handle_exception
    self.raise_uncaught_exception(exc)
  File "/home/telegrambot/.local/share/virtualenvs/AutoApp-g0zIqH6I/lib/python3.8/site-packages/rest_framework/views.py", line 480, in raise_uncaught_exception
    raise exc
  File "/home/telegrambot/.local/share/virtualenvs/AutoApp-g0zIqH6I/lib/python3.8/site-packages/rest_framework/views.py", line 506, in dispatch
    response = handler(request, *args, **kwargs)
  File "/home/telegrambot/AutoApp/Auth/views.py", line 177, in get
    data = ModelRegister.objects.get(id = kwargs['pk'])
  File "/home/telegrambot/.local/share/virtualenvs/AutoApp-g0zIqH6I/lib/python3.8/site-packages/django/db/models/manager.py", line 85, in manager_method
    return getattr(self.get_queryset(), name)(*args, **kwargs)
  File "/home/telegrambot/.local/share/virtualenvs/AutoApp-g0zIqH6I/lib/python3.8/site-packages/django/db/models/query.py", line 418, in get
    clone = self._chain() if self.query.combinator else self.filter(*args, **kwargs)
  File "/home/telegrambot/.local/share/virtualenvs/AutoApp-g0zIqH6I/lib/python3.8/site-packages/django/db/models/query.py", line 942, in filter
    return self._filter_or_exclude(False, *args, **kwargs)
  File "/home/telegrambot/.local/share/virtualenvs/AutoApp-g0zIqH6I/lib/python3.8/site-packages/django/db/models/query.py", line 962, in _filter_or_exclude
    clone._filter_or_exclude_inplace(negate, *args, **kwargs)
  File "/home/telegrambot/.local/share/virtualenvs/AutoApp-g0zIqH6I/lib/python3.8/site-packages/django/db/models/query.py", line 969, in _filter_or_exclude_inplace
    self._query.add_q(Q(*args, **kwargs))
  File "/home/telegrambot/.local/share/virtualenvs/AutoApp-g0zIqH6I/lib/python3.8/site-packages/django/db/models/sql/query.py", line 1358, in add_q
    clause, _ = self._add_q(q_object, self.used_aliases)
  File "/home/telegrambot/.local/share/virtualenvs/AutoApp-g0zIqH6I/lib/python3.8/site-packages/django/db/models/sql/query.py", line 1377, in _add_q
    child_clause, needed_inner = self.build_filter(
  File "/home/telegrambot/.local/share/virtualenvs/AutoApp-g0zIqH6I/lib/python3.8/site-packages/django/db/models/sql/query.py", line 1319, in build_filter
    condition = self.build_lookup(lookups, col, value)
  File "/home/telegrambot/.local/share/virtualenvs/AutoApp-g0zIqH6I/lib/python3.8/site-packages/django/db/models/sql/query.py", line 1165, in build_lookup
    lookup = lookup_class(lhs, rhs)
  File "/home/telegrambot/.local/share/virtualenvs/AutoApp-g0zIqH6I/lib/python3.8/site-packages/django/db/models/lookups.py", line 24, in __init__
    self.rhs = self.get_prep_lookup()
  File "/home/telegrambot/.local/share/virtualenvs/AutoApp-g0zIqH6I/lib/python3.8/site-packages/django/db/models/lookups.py", line 76, in get_prep_lookup
    return self.lhs.output_field.get_prep_value(self.rhs)
  File "/home/telegrambot/.local/share/virtualenvs/AutoApp-g0zIqH6I/lib/python3.8/site-packages/django/db/models/fields/__init__.py", line 1776, in get_prep_value
    raise e.__class__(
ValueError: Field 'id' expected a number but got 'null'.
